Workbook

Sheet 基础数据
C1: 公式 | E1: 公式 | H1: 公式 | I1: 公式 | K1: 公式 | L1: 公式 | M1: 下拉选项 | O1: 公式 | R1: 公式 | S1: 公式 | T1: 公式 | U1: 公式 | V1: 下拉选项 | W1: 公式
A2: 月份 | B2: 日期 | C2: 周 | D2: 周更改 | E2: 周几 | F2: 大区 | G2: DM | H2: 城市 | I2: 岗位号 | J2: MICS | K2: 入职时长 | L2: 入职时间划分 | M2: 目标患者画像 | N2: 提及次数 | O2: 医院Code | P2: 医院 | Q2: 客户 | R2: 客户类型 | S2: 红绿黑标 | T2: 专业方向 | U2: 科室 | V2: 患者类型 | W2: 预估
A3: 4月 | B3: 46113 | C3: =MONTH(B3)&TEXT(WEEKNUM(B3,2)-WEEKNUM(B3+1-DAY(B3),2)+1,"月第0周") -> 4月第1周 | D3: 4月第1周 | E3: =D3&"--"&"周"&WEEKDAY(B3,2) -> 4月第1周--周3 | F3: 钟君珊 | G3: 郑家成 | H3: =_xlfn.XLOOKUP(O3,匹配表1065!T:T,匹配表1065!W:W) -> 南京市 | I3: =_xlfn.XLOOKUP(O3,匹配表1065!T:T,匹配表1065!X:X) -> PME2006 | J3: 孙娟 | K3: {=_xlfn.XLOOKUP(J3,匹配表1065!Y:Y,匹配表1065!AA:AB)} -> 15 | L3: 3个月以上 | M3: 3、VM | N3: 1 | O3: =_xlfn.XLOOKUP(P3,匹配表1065!U:U,匹配表1065!T:T) -> HO00000965 | P3: 东南大学附属中大医院 | Q3: 耿磊钰 | R3: =_xlfn.XLOOKUP(Q3,匹配表1065!L:L,匹配表1065!O:O) -> A | S3: =IFERROR(_xlfn.XLOOKUP(Q3,匹配表1065!AI:AI,匹配表1065!AJ:AJ),"绿标") -> 绿标 | T3: {=_xlfn.XLOOKUP(Q3,匹配表1065!L:L,匹配表1065!M:N)} -> 头痛 | U3: 神经内科 | V3: 4-7次（中频） | W3: =_xlfn.XLOOKUP(M3,匹配表1065!D:D,匹配表1065!F:F)*N3 -> 12
A4: 4月 | B4: 46113 | C4: =MONTH(B4)&TEXT(WEEKNUM(B4,2)-WEEKNUM(B4+1-DAY(B4),2)+1,"月第0周") -> 4月第1周 | D4: 4月第1周 | E4: =D4&"--"&"周"&WEEKDAY(B4,2) -> 4月第1周--周3 | F4: 钟君珊 | G4: 郑家成 | H4: =_xlfn.XLOOKUP(O4,匹配表1065!T:T,匹配表1065!W:W) -> 南京市 | I4: =_xlfn.XLOOKUP(O4,匹配表1065!T:T,匹配表1065!X:X) -> PME2004 | J4: 杨帆 | K4: {=_xlfn.XLOOKUP(J4,匹配表1065!Y:Y,匹配表1065!AA:AB)} -> 11 | L4: 3个月以上 | M4: 1、中频 | N4: 1 | O4: =_xlfn.XLOOKUP(P4,匹配表1065!U:U,匹配表1065!T:T) -> HO00000972 | P4: 中国人民解放军东部战区总医院 | Q4: 刘玲 | R4: =_xlfn.XLOOKUP(Q4,匹配表1065!L:L,匹配表1065!O:O) -> A | S4: =IFERROR(_xlfn.XLOOKUP(Q4,匹配表1065!AI:AI,匹配表1065!AJ:AJ),"绿标") -> 绿标 | T4: {=_xlfn.XLOOKUP(Q4,匹配表1065!L:L,匹配表1065!M:N)} -> 头痛 | U4: 神经内科 | V4: 4-7次（中频） | W4: =_xlfn.XLOOKUP(M4,匹配表1065!D:D,匹配表1065!F:F)*N4 -> 4
A5: 4月 | B5: 46113 | C5: =MONTH(B5)&TEXT(WEEKNUM(B5,2)-WEEKNUM(B5+1-DAY(B5),2)+1,"月第0周") -> 4月第1周 | D5: 4月第1周 | E5: =D5&"--"&"周"&WEEKDAY(B5,2) -> 4月第1周--周3 | F5: 钟君珊 | G5: 郑家成 | H5: =_xlfn.XLOOKUP(O5,匹配表1065!T:T,匹配表1065!W:W) -> 南京市 | I5: =_xlfn.XLOOKUP(O5,匹配表1065!T:T,匹配表1065!X:X) -> PME2004 | J5: 杨帆 | K5: {=_xlfn.XLOOKUP(J5,匹配表1065!Y:Y,匹配表1065!AA:AB)} -> 11 | L5: 3个月以上 | M5: 1、中频 | N5: 1 | O5: =_xlfn.XLOOKUP(P5,匹配表1065!U:U,匹配表1065!T:T) -> HO00000972 | P5: 中国人民解放军东部战区总医院 | Q5: 蔡玉龙 | R5: =_xlfn.XLOOKUP(Q5,匹配表1065!L:L,匹配表1065!O:O) -> B | S5: =IFERROR(_xlfn.XLOOKUP(Q5,匹配表1065!AI:AI,匹配表1065!AJ:AJ),"绿标") -> 绿标 | T5: {=_xlfn.XLOOKUP(Q5,匹配表1065!L:L,匹配表1065!M:N)} -> 脑血管 | U5: 神经内科 | V5: 4-7次（中频） | W5: =_xlfn.XLOOKUP(M5,匹配表1065!D:D,匹配表1065!F:F)*N5 -> 4
A6: 4月 | B6: 46113 | C6: =MONTH(B6)&TEXT(WEEKNUM(B6,2)-WEEKNUM(B6+1-DAY(B6),2)+1,"月第0周") -> 4月第1周 | D6: 4月第1周 | E6: =D6&"--"&"周"&WEEKDAY(B6,2) -> 4月第1周--周3 | F6: 钟君珊 | G6: 郑家成 | H6: =_xlfn.XLOOKUP(O6,匹配表1065!T:T,匹配表1065!W:W) -> 南京市 | I6: =_xlfn.XLOOKUP(O6,匹配表1065!T:T,匹配表1065!X:X) -> PME2039 | J6: 盖奕彤 | K6: {=_xlfn.XLOOKUP(J6,匹配表1065!Y:Y,匹配表1065!AA:AB)} -> 7 | L6: 3个月以上 | M6: 1、中频 | N6: 1 | O6: =_xlfn.XLOOKUP(P6,匹配表1065!U:U,匹配表1065!T:T) -> HO00000971 | P6: 江苏省中医院 | Q6: 崔春丽 | R6: =_xlfn.XLOOKUP(Q6,匹配表1065!L:L,匹配表1065!O:O) -> A | S6: =IFERROR(_xlfn.XLOOKUP(Q6,匹配表1065!AI:AI,匹配表1065!AJ:AJ),"绿标") -> 绿标 | T6: {=_xlfn.XLOOKUP(Q6,匹配表1065!L:L,匹配表1065!M:N)} -> 头痛 | U6: 神经内科 | V6: 大于8次（高频） | W6: =_xlfn.XLOOKUP(M6,匹配表1065!D:D,匹配表1065!F:F)*N6 -> 4
A7: 4月 | B7: 46113 | C7: =MONTH(B7)&TEXT(WEEKNUM(B7,2)-WEEKNUM(B7+1-DAY(B7),2)+1,"月第0周") -> 4月第1周 | D7: 4月第1周 | E7: =D7&"--"&"周"&WEEKDAY(B7,2) -> 4月第1周--周3 | F7: 钟君珊 | G7: 郑家成 | H7: =_xlfn.XLOOKUP(O7,匹配表1065!T:T,匹配表1065!W:W) -> 镇江市 | I7: =_xlfn.XLOOKUP(O7,匹配表1065!T:T,匹配表1065!X:X) -> PME2039 | J7: 盖奕彤 | K7: {=_xlfn.XLOOKUP(J7,匹配表1065!Y:Y,匹配表1065!AA:AB)} -> 7 | L7: 3个月以上 | M7: 1、中频 | N7: 1 | O7: =_xlfn.XLOOKUP(P7,匹配表1065!U:U,匹配表1065!T:T) -> HO00001015 | P7: 镇江市第一人民医院 | Q7: 周志奎 | R7: =_xlfn.XLOOKUP(Q7,匹配表1065!L:L,匹配表1065!O:O) -> A | S7: =IFERROR(_xlfn.XLOOKUP(Q7,匹配表1065!AI:AI,匹配表1065!AJ:AJ),"绿标") -> 绿标 | T7: {=_xlfn.XLOOKUP(Q7,匹配表1065!L:L,匹配表1065!M:N)} -> 头痛 | U7: 神经内科 | V7: 4-7次（中频） | W7: =_xlfn.XLOOKUP(M7,匹配表1065!D:D,匹配表1065!F:F)*N7 -> 4
A8: 4月 | B8: 46113 | C8: =MONTH(B8)&TEXT(WEEKNUM(B8,2)-WEEKNUM(B8+1-DAY(B8),2)+1,"月第0周") -> 4月第1周 | D8: 4月第1周 | E8: =D8&"--"&"周"&WEEKDAY(B8,2) -> 4月第1周--周3 | F8: 钟君珊 | G8: 郑家成 | H8: =_xlfn.XLOOKUP(O8,匹配表1065!T:T,匹配表1065!W:W) -> 常州市 | I8: =_xlfn.XLOOKUP(O8,匹配表1065!T:T,匹配表1065!X:X) -> PME2015 | J8: 缪苏琴 | K8: {=_xlfn.XLOOKUP(J8,匹配表1065!Y:Y,匹配表1065!AA:AB)} -> 9 | L8: 3个月以上 | M8: 1、中频 | N8: 1 | O8: =_xlfn.XLOOKUP(P8,匹配表1065!U:U,匹配表1065!T:T) -> HO00015998 | P8: 常州市武进中医医院 | Q8: 王凤英 | R8: =_xlfn.XLOOKUP(Q8,匹配表1065!L:L,匹配表1065!O:O) -> B | S8: =IFERROR(_xlfn.XLOOKUP(Q8,匹配表1065!AI:AI,匹配表1065!AJ:AJ),"绿标") -> 绿标 | T8: {=_xlfn.XLOOKUP(Q8,匹配表1065!L:L,匹配表1065!M:N)} -> 脑血管 | U8: 神经内科 | V8: 大于8次（高频） | W8: =_xlfn.XLOOKUP(M8,匹配表1065!D:D,匹配表1065!F:F)*N8 -> 4
A9: 4月 | B9: 46113 | C9: =MONTH(B9)&TEXT(WEEKNUM(B9,2)-WEEKNUM(B9+1-DAY(B9),2)+1,"月第0周") -> 4月第1周 | D9: 4月第1周 | E9: =D9&"--"&"周"&WEEKDAY(B9,2) -> 4月第1周--周3 | F9: 钟君珊 | G9: 郑家成 | H9: =_xlfn.XLOOKUP(O9,匹配表1065!T:T,匹配表1065!W:W) -> 常州市 | I9: =_xlfn.XLOOKUP(O9,匹配表1065!T:T,匹配表1065!X:X) -> PME2015 | J9: 缪苏琴 | K9: {=_xlfn.XLOOKUP(J9,匹配表1065!Y:Y,匹配表1065!AA:AB)} -> 9 | L9: 3个月以上 | M9: 1、中频 | N9: 1 | O9: =_xlfn.XLOOKUP(P9,匹配表1065!U:U,匹配表1065!T:T) -> HO00016083 | P9: 常州市妇幼保健院 | Q9: 郑秀琴 | R9: =_xlfn.XLOOKUP(Q9,匹配表1065!L:L,匹配表1065!O:O) -> B | S9: =IFERROR(_xlfn.XLOOKUP(Q9,匹配表1065!AI:AI,匹配表1065!AJ:AJ),"绿标") -> 红标 | T9: {=_xlfn.XLOOKUP(Q9,匹配表1065!L:L,匹配表1065!M:N)} -> 脑血管 | U9: 神经内科 | V9: 大于8次（高频） | W9: =_xlfn.XLOOKUP(M9,匹配表1065!D:D,匹配表1065!F:F)*N9 -> 4
A10: 4月 | B10: 46113 | C10: =MONTH(B10)&TEXT(WEEKNUM(B10,2)-WEEKNUM(B10+1-DAY(B10),2)+1,"月第0周") -> 4月第1周 | D10: 4月第1周 | E10: =D10&"--"&"周"&WEEKDAY(B10,2) -> 4月第1周--周3 | F10: 钟君珊 | G10: 郑家成 | H10: =_xlfn.XLOOKUP(O10,匹配表1065!T:T,匹配表1065!W:W) -> 南京市 | I10: =_xlfn.XLOOKUP(O10,匹配表1065!T:T,匹配表1065!X:X) -> PME2040 | J10: 王玉婷 | K10: {=_xlfn.XLOOKUP(J10,匹配表1065!Y:Y,匹配表1065!AA:AB)} -> #N/A | M10: 1、中频 | N10: 1 | O10: =_xlfn.XLOOKUP(P10,匹配表1065!U:U,匹配表1065!T:T) -> HO00000966 | P10: 南京医科大学第二附属医院 | Q10: 吴晋 | R10: =_xlfn.XLOOKUP(Q10,匹配表1065!L:L,匹配表1065!O:O) -> B | S10: =IFERROR(_xlfn.XLOOKUP(Q10,匹配表1065!AI:AI,匹配表1065!AJ:AJ),"绿标") -> 红标 | T10: {=_xlfn.XLOOKUP(Q10,匹配表1065!L:L,匹配表1065!M:N)} -> 脑血管 | U10: 神经内科 | V10: 大于8次（高频） | W10: =_xlfn.XLOOKUP(M10,匹配表1065!D:D,匹配表1065!F:F)*N10 -> 4
A11: 4月 | B11: 46113 | C11: =MONTH(B11)&TEXT(WEEKNUM(B11,2)-WEEKNUM(B11+1-DAY(B11),2)+1,"月第0周") -> 4月第1周 | D11: 4月第1周 | E11: =D11&"--"&"周"&WEEKDAY(B11,2) -> 4月第1周--周3 | F11: 钟君珊 | G11: 郑家成 | H11: =_xlfn.XLOOKUP(O11,匹配表1065!T:T,匹配表1065!W:W) -> 南京市 | I11: =_xlfn.XLOOKUP(O11,匹配表1065!T:T,匹配表1065!X:X) -> PME2040 | J11: 王玉婷 | K11: {=_xlfn.XLOOKUP(J11,匹配表1065!Y:Y,匹配表1065!AA:AB)} -> #N/A | M11: 1、中频 | N11: 1 | O11: =_xlfn.XLOOKUP(P11,匹配表1065!U:U,匹配表1065!T:T) -> HO00000966 | P11: 南京医科大学第二附属医院 | Q11: 刘玮 | R11: =_xlfn.XLOOKUP(Q11,匹配表1065!L:L,匹配表1065!O:O) -> A | S11: =IFERROR(_xlfn.XLOOKUP(Q11,匹配表1065!AI:AI,匹配表1065!AJ:AJ),"绿标") -> 绿标 | T11: {=_xlfn.XLOOKUP(Q11,匹配表1065!L:L,匹配表1065!M:N)} -> 头痛 | U11: 神经内科 | V11: 4-7次（中频） | W11: =_xlfn.XLOOKUP(M11,匹配表1065!D:D,匹配表1065!F:F)*N11 -> 4
A12: 4月 | B12: 46113 | C12: =MONTH(B12)&TEXT(WEEKNUM(B12,2)-WEEKNUM(B12+1-DAY(B12),2)+1,"月第0周") -> 4月第1周 | D12: 4月第1周 | E12: =D12&"--"&"周"&WEEKDAY(B12,2) -> 4月第1周--周3 | F12: 钟君珊 | G12: 郑家成 | H12: =_xlfn.XLOOKUP(O12,匹配表1065!T:T,匹配表1065!W:W) -> 南京市 | I12: =_xlfn.XLOOKUP(O12,匹配表1065!T:T,匹配表1065!X:X) -> PME2005 | J12: 徐燕 | K12: {=_xlfn.XLOOKUP(J12,匹配表1065!Y:Y,匹配表1065!AA:AB)} -> 3 | L12: 3个月以上 | M12: 2、高频 | N12: 1 | O12: =_xlfn.XLOOKUP(P12,匹配表1065!U:U,匹配表1065!T:T) -> HO00000975 | P12: 南京脑科医院 | Q12: 刘斌 | R12: =_xlfn.XLOOKUP(Q12,匹配表1065!L:L,匹配表1065!O:O) -> C | S12: =IFERROR(_xlfn.XLOOKUP(Q12,匹配表1065!AI:AI,匹配表1065!AJ:AJ),"绿标") -> 绿标 | T12: {=_xlfn.XLOOKUP(Q12,匹配表1065!L:L,匹配表1065!M:N)} -> 眩晕 | U12: 神经内科 | V12: 小于4次（低频） | W12: =_xlfn.XLOOKUP(M12,匹配表1065!D:D,匹配表1065!F:F)*N12 -> 8
A13: 4月 | B13: 46113 | C13: =MONTH(B13)&TEXT(WEEKNUM(B13,2)-WEEKNUM(B13+1-DAY(B13),2)+1,"月第0周") -> 4月第1周 | D13: 4月第1周 | E13: =D13&"--"&"周"&WEEKDAY(B13,2) -> 4月第1周--周3 | F13: 钟君珊 | G13: 郑家成 | H13: =_xlfn.XLOOKUP(O13,匹配表1065!T:T,匹配表1065!W:W) -> 南京市 | I13: =_xlfn.XLOOKUP(O13,匹配表1065!T:T,匹配表1065!X:X) -> PME2005 | J13: 徐燕 | K13: {=_xlfn.XLOOKUP(J13,匹配表1065!Y:Y,匹配表1065!AA:AB)} -> 3 | L13: 3个月以上 | M13: 1、中频 | N13: 1 | O13: =_xlfn.XLOOKUP(P13,匹配表1065!U:U,匹配表1065!T:T) -> HO00000975 | P13: 南京脑科医院 | Q13: 陈志璐 | R13: =_xlfn.XLOOKUP(Q13,匹配表1065!L:L,匹配表1065!O:O) -> B | S13: =IFERROR(_xlfn.XLOOKUP(Q13,匹配表1065!AI:AI,匹配表1065!AJ:AJ),"绿标") -> 绿标 | T13: {=_xlfn.XLOOKUP(Q13,匹配表1065!L:L,匹配表1065!M:N)} -> 脑血管 | U13: 神经内科 | V13: 大于8次（高频） | W13: =_xlfn.XLOOKUP(M13,匹配表1065!D:D,匹配表1065!F:F)*N13 -> 4
A14: 4月 | B14: 46113 | C14: =MONTH(B14)&TEXT(WEEKNUM(B14,2)-WEEKNUM(B14+1-DAY(B14),2)+1,"月第0周") -> 4月第1周 | D14: 4月第1周 | E14: =D14&"--"&"周"&WEEKDAY(B14,2) -> 4月第1周--周3 | F14: 钟君珊 | G14: 郑家成 | H14: =_xlfn.XLOOKUP(O14,匹配表1065!T:T,匹配表1065!W:W) -> 扬州市 | I14: =_xlfn.XLOOKUP(O14,匹配表1065!T:T,匹配表1065!X:X) -> PME2012 | J14: 高佳怡 | K14: {=_xlfn.XLOOKUP(J14,匹配表1065!Y:Y,匹配表1065!AA:AB)} -> 13 | L14: 3个月以上 | M14: 3、VM | N14: 1 | O14: =_xlfn.XLOOKUP(P14,匹配表1065!U:U,匹配表1065!T:T) -> HO00000968 | P14: 江苏省苏北人民医院 | Q14: 陈兰兰 | R14: =_xlfn.XLOOKUP(Q14,匹配表1065!L:L,匹配表1065!O:O) -> A | S14: =IFERROR(_xlfn.XLOOKUP(Q14,匹配表1065!AI:AI,匹配表1065!AJ:AJ),"绿标") -> 红标 | T14: {=_xlfn.XLOOKUP(Q14,匹配表1065!L:L,匹配表1065!M:N)} -> 头痛 | U14: 神经内科 | V14: 4-7次（中频） | W14: =_xlfn.XLOOKUP(M14,匹配表1065!D:D,匹配表1065!F:F)*N14 -> 12
A15: 4月 | B15: 46113 | C15: =MONTH(B15)&TEXT(WEEKNUM(B15,2)-WEEKNUM(B15+1-DAY(B15),2)+1,"月第0周") -> 4月第1周 | D15: 4月第1周 | E15: =D15&"--"&"周"&WEEKDAY(B15,2) -> 4月第1周--周3 | F15: 钟君珊 | G15: 孟鈃 | H15: =_xlfn.XLOOKUP(O15,匹配表1065!T:T,匹配表1065!W:W) -> 南京市 | I15: =_xlfn.XLOOKUP(O15,匹配表1065!T:T,匹配表1065!X:X) -> PME2001 | J15: 王方方 | K15: {=_xlfn.XLOOKUP(J15,匹配表1065!Y:Y,匹配表1065!AA:AB)} -> 31 | L15: 3个月以上 | M15: 3、VM | N15: 1 | O15: =_xlfn.XLOOKUP(P15,匹配表1065!U:U,匹配表1065!T:T) -> HO00000958 | P15: 江苏省人民医院 | Q15: 董欣 | R15: =_xlfn.XLOOKUP(Q15,匹配表1065!L:L,匹配表1065!O:O) -> A | S15: =IFERROR(_xlfn.XLOOKUP(Q15,匹配表1065!AI:AI,匹配表1065!AJ:AJ),"绿标") -> 红标 | T15: {=_xlfn.XLOOKUP(Q15,匹配表1065!L:L,匹配表1065!M:N)} -> 头痛 | U15: 神经内科 | V15: CM/MOH | W15: =_xlfn.XLOOKUP(M15,匹配表1065!D:D,匹配表1065!F:F)*N15 -> 12
A16: 4月 | B16: 46113 | C16: =MONTH(B16)&TEXT(WEEKNUM(B16,2)-WEEKNUM(B16+1-DAY(B16),2)+1,"月第0周") -> 4月第1周 | D16: 4月第1周 | E16: =D16&"--"&"周"&WEEKDAY(B16,2) -> 4月第1周--周3 | F16: 钟君珊 | G16: 孟鈃 | H16: =_xlfn.XLOOKUP(O16,匹配表1065!T:T,匹配表1065!W:W) -> 南京市 | I16: =_xlfn.XLOOKUP(O16,匹配表1065!T:T,匹配表1065!X:X) -> PME2001 | J16: 王方方 | K16: {=_xlfn.XLOOKUP(J16,匹配表1065!Y:Y,匹配表1065!AA:AB)} -> 31 | L16: 3个月以上 | M16: 3、VM | N16: 1 | O16: =_xlfn.XLOOKUP(P16,匹配表1065!U:U,匹配表1065!T:T) -> HO00000958 | P16: 江苏省人民医院 | Q16: 顾萍 | R16: =_xlfn.XLOOKUP(Q16,匹配表1065!L:L,匹配表1065!O:O) -> A | S16: =IFERROR(_xlfn.XLOOKUP(Q16,匹配表1065!AI:AI,匹配表1065!AJ:AJ),"绿标") -> 红标 | T16: {=_xlfn.XLOOKUP(Q16,匹配表1065!L:L,匹配表1065!M:N)} -> 头痛 | U16: 神经内科 | V16: CM/MOH | W16: =_xlfn.XLOOKUP(M16,匹配表1065!D:D,匹配表1065!F:F)*N16 -> 12
A17: 4月 | B17: 46113 | C17: =MONTH(B17)&TEXT(WEEKNUM(B17,2)-WEEKNUM(B17+1-DAY(B17),2)+1,"月第0周") -> 4月第1周 | D17: 4月第1周 | E17: =D17&"--"&"周"&WEEKDAY(B17,2) -> 4月第1周--周3 | F17: 钟君珊 | G17: 孟鈃 | H17: =_xlfn.XLOOKUP(O17,匹配表1065!T:T,匹配表1065!W:W) -> 南京市 | I17: =_xlfn.XLOOKUP(O17,匹配表1065!T:T,匹配表1065!X:X) -> PME2001 | J17: 王方方 | K17: {=_xlfn.XLOOKUP(J17,匹配表1065!Y:Y,匹配表1065!AA:AB)} -> 31 | L17: 3个月以上 | M17: 2、高频 | N17: 1 | O17: =_xlfn.XLOOKUP(P17,匹配表1065!U:U,匹配表1065!T:T) -> HO00000958 | P17: 江苏省人民医院 | Q17: 赵晓埝 | R17: =_xlfn.XLOOKUP(Q17,匹配表1065!L:L,匹配表1065!O:O) -> C | S17: =IFERROR(_xlfn.XLOOKUP(Q17,匹配表1065!AI:AI,匹配表1065!AJ:AJ),"绿标") -> 绿标 | T17: {=_xlfn.XLOOKUP(Q17,匹配表1065!L:L,匹配表1065!M:N)} -> 眩晕 | U17: 耳鼻喉科 | V17: 焦虑抑郁共病 | W17: =_xlfn.XLOOKUP(M17,匹配表1065!D:D,匹配表1065!F:F)*N17 -> 8
A18: 4月 | B18: 46113 | C18: =MONTH(B18)&TEXT(WEEKNUM(B18,2)-WEEKNUM(B18+1-DAY(B18),2)+1,"月第0周") -> 4月第1周 | D18: 4月第1周 | E18: =D18&"--"&"周"&WEEKDAY(B18,2) -> 4月第1周--周3 | F18: 钟君珊 | G18: 孟鈃 | H18: =_xlfn.XLOOKUP(O18,匹配表1065!T:T,匹配表1065!W:W) -> 淮安市 | I18: =_xlfn.XLOOKUP(O18,匹配表1065!T:T,匹配表1065!X:X) -> PME2041 | J18: 徐自豪 | K18: {=_xlfn.XLOOKUP(J18,匹配表1065!Y:Y,匹配表1065!AA:AB)} -> 5 | L18: 3个月以上 | M18: 1、中频 | N18: 1 | O18: =_xlfn.XLOOKUP(P18,匹配表1065!U:U,匹配表1065!T:T) -> HO00000992 | P18: 淮安市第一人民医院 | Q18: 蔡诗昆 | R18: =_xlfn.XLOOKUP(Q18,匹配表1065!L:L,匹配表1065!O:O) -> D | S18: =IFERROR(_xlfn.XLOOKUP(Q18,匹配表1065!AI:AI,匹配表1065!AJ:AJ),"绿标") -> 绿标 | T18: {=_xlfn.XLOOKUP(Q18,匹配表1065!L:L,匹配表1065!M:N)} -> 眩晕 | U18: 神经内科 | V18: 小于4次（低频） | W18: =_xlfn.XLOOKUP(M18,匹配表1065!D:D,匹配表1065!F:F)*N18 -> 4
A19: 4月 | B19: 46113 | C19: =MONTH(B19)&TEXT(WEEKNUM(B19,2)-WEEKNUM(B19+1-DAY(B19),2)+1,"月第0周") -> 4月第1周 | D19: 4月第1周 | E19: =D19&"--"&"周"&WEEKDAY(B19,2) -> 4月第1周--周3 | F19: 钟君珊 | G19: 孟鈃 | H19: =_xlfn.XLOOKUP(O19,匹配表1065!T:T,匹配表1065!W:W) -> 连云港市 | I19: =_xlfn.XLOOKUP(O19,匹配表1065!T:T,匹配表1065!X:X) -> PME2042 | J19: 黄燕儿 | K19: {=_xlfn.XLOOKUP(J19,匹配表1065!Y:Y,匹配表1065!AA:AB)} -> 7 | L19: 3个月以上 | M19: 1、中频 | N19: 1 | O19: =_xlfn.XLOOKUP(P19,匹配表1065!U:U,匹配表1065!T:T) -> HO00001004 | P19: 连云港市第一人民医院 | Q19: 张永进 | R19: =_xlfn.XLOOKUP(Q19,匹配表1065!L:L,匹配表1065!O:O) -> B | S19: =IFERROR(_xlfn.XLOOKUP(Q19,匹配表1065!AI:AI,匹配表1065!AJ:AJ),"绿标") -> 绿标 | T19: {=_xlfn.XLOOKUP(Q19,匹配表1065!L:L,匹配表1065!M:N)} -> 脑血管 | U19: 神经内科 | V19: 焦虑抑郁共病 | W19: =_xlfn.XLOOKUP(M19,匹配表1065!D:D,匹配表1065!F:F)*N19 -> 4
A20: 4月 | B20: 46113 | C20: =MONTH(B20)&TEXT(WEEKNUM(B20,2)-WEEKNUM(B20+1-DAY(B20),2)+1,"月第0周") -> 4月第1周 | D20: 4月第1周 | E20: =D20&"--"&"周"&WEEKDAY(B20,2) -> 4月第1周--周3 | F20: 钟君珊 | G20: 孟鈃 | H20: =_xlfn.XLOOKUP(O20,匹配表1065!T:T,匹配表1065!W:W) -> 南京市 | I20: =_xlfn.XLOOKUP(O20,匹配表1065!T:T,匹配表1065!X:X) -> PME2001 | J20: 芦晓辉 | K20: {=_xlfn.XLOOKUP(J20,匹配表1065!Y:Y,匹配表1065!AA:AB)} -> 8 | L20: 3个月以上 | M20: 2、高频 | N20: 1 | O20: =_xlfn.XLOOKUP(P20,匹配表1065!U:U,匹配表1065!T:T) -> HO00000958 | P20: 江苏省人民医院 | Q20: 曾彦英 | R20: =_xlfn.XLOOKUP(Q20,匹配表1065!L:L,匹配表1065!O:O) -> C | S20: =IFERROR(_xlfn.XLOOKUP(Q20,匹配表1065!AI:AI,匹配表1065!AJ:AJ),"绿标") -> 绿标 | T20: {=_xlfn.XLOOKUP(Q20,匹配表1065!L:L,匹配表1065!M:N)} -> 眩晕 | U20: 神经内科 | V20: 焦虑抑郁共病 | W20: =_xlfn.XLOOKUP(M20,匹配表1065!D:D,匹配表1065!F:F)*N20 -> 8
A21: 4月 | B21: 46113 | C21: =MONTH(B21)&TEXT(WEEKNUM(B21,2)-WEEKNUM(B21+1-DAY(B21),2)+1,"月第0周") -> 4月第1周 | D21: 4月第1周 | E21: =D21&"--"&"周"&WEEKDAY(B21,2) -> 4月第1周--周3 | F21: 钟君珊 | G21: 孟鈃 | H21: =_xlfn.XLOOKUP(O21,匹配表1065!T:T,匹配表1065!W:W) -> 南京市 | I21: =_xlfn.XLOOKUP(O21,匹配表1065!T:T,匹配表1065!X:X) -> PME2037 | J21: 芦晓辉 | K21: {=_xlfn.XLOOKUP(J21,匹配表1065!Y:Y,匹配表1065!AA:AB)} -> 8 | L21: 3个月以上 | M21: 1、中频 | N21: 1 | O21: =_xlfn.XLOOKUP(P21,匹配表1065!U:U,匹配表1065!T:T) -> HO00046044 | P21: 江苏省妇幼保健院 | Q21: 浦丹华 | R21: =_xlfn.XLOOKUP(Q21,匹配表1065!L:L,匹配表1065!O:O) -> D | S21: =IFERROR(_xlfn.XLOOKUP(Q21,匹配表1065!AI:AI,匹配表1065!AJ:AJ),"绿标") -> 绿标 | T21: {=_xlfn.XLOOKUP(Q21,匹配表1065!L:L,匹配表1065!M:N)} -> 其他 | U21: 其他 | V21: 小于4次（低频） | W21: =_xlfn.XLOOKUP(M21,匹配表1065!D:D,匹配表1065!F:F)*N21 -> 4
A22: 4月 | B22: 46113 | C22: =MONTH(B22)&TEXT(WEEKNUM(B22,2)-WEEKNUM(B22+1-DAY(B22),2)+1,"月第0周") -> 4月第1周 | D22: 4月第1周 | E22: =D22&"--"&"周"&WEEKDAY(B22,2) -> 4月第1周--周3 | F22: 钟君珊 | G22: 孟鈃 | H22: =_xlfn.XLOOKUP(O22,匹配表1065!T:T,匹配表1065!W:W) -> 徐州市 | I22: =_xlfn.XLOOKUP(O22,匹配表1065!T:T,匹配表1065!X:X) -> PME2008 | J22: 章智程 | K22: {=_xlfn.XLOOKUP(J22,匹配表1065!Y:Y,匹配表1065!AA:AB)} -> 19 | L22: 3个月以上 | M22: 3、VM | N22: 1 | O22: =_xlfn.XLOOKUP(P22,匹配表1065!U:U,匹配表1065!T:T) -> HO00001134 | P22: 徐州矿务集团总医院暨徐州医科大学院第二附属医院 | Q22: 单君君 | R22: =_xlfn.XLOOKUP(Q22,匹配表1065!L:L,匹配表1065!O:O) -> B | S22: =IFERROR(_xlfn.XLOOKUP(Q22,匹配表1065!AI:AI,匹配表1065!AJ:AJ),"绿标") -> 黑标 | T22: {=_xlfn.XLOOKUP(Q22,匹配表1065!L:L,匹配表1065!M:N)} -> 抑郁焦虑 | U22: 神经内科 | V22: CM/MOH | W22: =_xlfn.XLOOKUP(M22,匹配表1065!D:D,匹配表1065!F:F)*N22 -> 12
A23: 4月 | B23: 46113 | C23: =MONTH(B23)&TEXT(WEEKNUM(B23,2)-WEEKNUM(B23+1-DAY(B23),2)+1,"月第0周") -> 4月第1周 | D23: 4月第1周 | E23: =D23&"--"&"周"&WEEKDAY(B23,2) -> 4月第1周--周3 | F23: 钟君珊 | G23: 孟鈃 | H23: =_xlfn.XLOOKUP(O23,匹配表1065!T:T,匹配表1065!W:W) -> 南京市 | I23: =_xlfn.XLOOKUP(O23,匹配表1065!T:T,匹配表1065!X:X) -> PME2002 | J23: 罗世懿 | K23: {=_xlfn.XLOOKUP(J23,匹配表1065!Y:Y,匹配表1065!AA:AB)} -> 31 | L23: 3个月以上 | M23: 3、VM | N23: 1 | O23: =_xlfn.XLOOKUP(P23,匹配表1065!U:U,匹配表1065!T:T) -> HO00111156 | P23: 泰康仙林鼓楼医院有限公司 | Q23: 许爱刚 | R23: =_xlfn.XLOOKUP(Q23,匹配表1065!L:L,匹配表1065!O:O) -> D | S23: =IFERROR(_xlfn.XLOOKUP(Q23,匹配表1065!AI:AI,匹配表1065!AJ:AJ),"绿标") -> 红标 | T23: {=_xlfn.XLOOKUP(Q23,匹配表1065!L:L,匹配表1065!M:N)} -> 头痛 | U23: 神经内科 | V23: CM/MOH | W23: =_xlfn.XLOOKUP(M23,匹配表1065!D:D,匹配表1065!F:F)*N23 -> 12
... A78: 4月 | B78: 46114 | C78: =MONTH(B78)&TEXT(WEEKNUM(B78,2)-WEEKNUM(B78+1-DAY(B78),2)+1,"月第0周") -> 4月第1周 | D78: 4月第1周 | E78: =D78&"--"&"周"&WEEKDAY(B78,2) -> 4月第1周--周4 | F78: 钟君珊 | G78: 郑家成 | H78: =_xlfn.XLOOKUP(O78,匹配表1065!T:T,匹配表1065!W:W) -> 镇江市 | I78: =_xlfn.XLOOKUP(O78,匹配表1065!T:T,匹配表1065!X:X) -> PME2039 | J78: 盖奕彤 | K78: {=_xlfn.XLOOKUP(J78,匹配表1065!Y:Y,匹配表1065!AA:AB)} -> 7 | L78: 3个月以上 | M78: 3、VM | N78: 1 | O78: =_xlfn.XLOOKUP(P78,匹配表1065!U:U,匹配表1065!T:T) -> HO00001015 | P78: 镇江市第一人民医院 | Q78: 陈晓鹏 | R78: =_xlfn.XLOOKUP(Q78,匹配表1065!L:L,匹配表1065!O:O) -> B | S78: =IFERROR(_xlfn.XLOOKUP(Q78,匹配表1065!AI:AI,匹配表1065!AJ:AJ),"绿标") -> 绿标 | T78: {=_xlfn.XLOOKUP(Q78,匹配表1065!L:L,匹配表1065!M:N)} -> 脑血管 | U78: 神经内科 | V78: 焦虑抑郁共病 | W78: =_xlfn.XLOOKUP(M78,匹配表1065!D:D,匹配表1065!F:F)*N78 -> 12
A79: 4月 | B79: 46114 | C79: =MONTH(B79)&TEXT(WEEKNUM(B79,2)-WEEKNUM(B79+1-DAY(B79),2)+1,"月第0周") -> 4月第1周 | D79: 4月第1周 | E79: =D79&"--"&"周"&WEEKDAY(B79,2) -> 4月第1周--周4 | F79: 钟君珊 | G79: 郑家成 | H79: =_xlfn.XLOOKUP(O79,匹配表1065!T:T,匹配表1065!W:W) -> 南京市 | I79: =_xlfn.XLOOKUP(O79,匹配表1065!T:T,匹配表1065!X:X) -> PME2040 | J79: 王玉婷 | K79: {=_xlfn.XLOOKUP(J79,匹配表1065!Y:Y,匹配表1065!AA:AB)} -> #N/A | M79: 3、VM | N79: 1 | O79: =_xlfn.XLOOKUP(P79,匹配表1065!U:U,匹配表1065!T:T) -> HO00000966 | P79: 南京医科大学第二附属医院 | Q79: 潘凤华 | R79: =_xlfn.XLOOKUP(Q79,匹配表1065!L:L,匹配表1065!O:O) -> A | S79: =IFERROR(_xlfn.XLOOKUP(Q79,匹配表1065!AI:AI,匹配表1065!AJ:AJ),"绿标") -> 绿标 | T79: {=_xlfn.XLOOKUP(Q79,匹配表1065!L:L,匹配表1065!M:N)} -> 头痛 | U79: 神经内科 | V79: 焦虑抑郁共病 | W79: =_xlfn.XLOOKUP(M79,匹配表1065!D:D,匹配表1065!F:F)*N79 -> 12
A80: 4月 | B80: 46114 | C80: =MONTH(B80)&TEXT(WEEKNUM(B80,2)-WEEKNUM(B80+1-DAY(B80),2)+1,"月第0周") -> 4月第1周 | D80: 4月第1周 | E80: =D80&"--"&"周"&WEEKDAY(B80,2) -> 4月第1周--周4 | F80: 钟君珊 | G80: 郑家成 | H80: =_xlfn.XLOOKUP(O80,匹配表1065!T:T,匹配表1065!W:W) -> 扬州市 | I80: =_xlfn.XLOOKUP(O80,匹配表1065!T:T,匹配表1065!X:X) -> PME2012 | J80: 高佳怡 | K80: {=_xlfn.XLOOKUP(J80,匹配表1065!Y:Y,匹配表1065!AA:AB)} -> 13 | L80: 3个月以上 | M80: 3、VM | N80: 1 | O80: =_xlfn.XLOOKUP(P80,匹配表1065!U:U,匹配表1065!T:T) -> HO00000968 | P80: 江苏省苏北人民医院 | Q80: 陈兰兰 | R80: =_xlfn.XLOOKUP(Q80,匹配表1065!L:L,匹配表1065!O:O) -> A | S80: =IFERROR(_xlfn.XLOOKUP(Q80,匹配表1065!AI:AI,匹配表1065!AJ:AJ),"绿标") -> 红标 | T80: {=_xlfn.XLOOKUP(Q80,匹配表1065!L:L,匹配表1065!M:N)} -> 头痛 | U80: 神经内科 | V80: 大于8次（高频） | W80: =_xlfn.XLOOKUP(M80,匹配表1065!D:D,匹配表1065!F:F)*N80 -> 12
A81: 4月 | B81: 46114 | C81: =MONTH(B81)&TEXT(WEEKNUM(B81,2)-WEEKNUM(B81+1-DAY(B81),2)+1,"月第0周") -> 4月第1周 | D81: 4月第1周 | E81: =D81&"--"&"周"&WEEKDAY(B81,2) -> 4月第1周--周4 | F81: 钟君珊 | G81: 郑家成 | H81: =_xlfn.XLOOKUP(O81,匹配表1065!T:T,匹配表1065!W:W) -> 泰州市 | I81: =_xlfn.XLOOKUP(O81,匹配表1065!T:T,匹配表1065!X:X) -> PME2012 | J81: 高佳怡 | K81: {=_xlfn.XLOOKUP(J81,匹配表1065!Y:Y,匹配表1065!AA:AB)} -> 13 | L81: 3个月以上 | M81: 2、高频 | N81: 1 | O81: =_xlfn.XLOOKUP(P81,匹配表1065!U:U,匹配表1065!T:T) -> HO00000954 | P81: 泰州市第二人民医院 | Q81: 茆华武 | R81: =_xlfn.XLOOKUP(Q81,匹配表1065!L:L,匹配表1065!O:O) -> B | S81: =IFERROR(_xlfn.XLOOKUP(Q81,匹配表1065!AI:AI,匹配表1065!AJ:AJ),"绿标") -> 绿标 | T81: {=_xlfn.XLOOKUP(Q81,匹配表1065!L:L,匹配表1065!M:N)} -> 脑血管 | U81: 神经内科 | V81: 大于8次（高频） | W81: =_xlfn.XLOOKUP(M81,匹配表1065!D:D,匹配表1065!F:F)*N81 -> 8
A82: 4月 | B82: 46114 | C82: =MONTH(B82)&TEXT(WEEKNUM(B82,2)-WEEKNUM(B82+1-DAY(B82),2)+1,"月第0周") -> 4月第1周 | D82: 4月第1周 | E82: =D82&"--"&"周"&WEEKDAY(B82,2) -> 4月第1周--周4 | F82: 钟君珊 | G82: 郑家成 | H82: =_xlfn.XLOOKUP(O82,匹配表1065!T:T,匹配表1065!W:W) -> 常州市 | I82: =_xlfn.XLOOKUP(O82,匹配表1065!T:T,匹配表1065!X:X) -> PME2015 | J82: 缪苏琴 | K82: {=_xlfn.XLOOKUP(J82,匹配表1065!Y:Y,匹配表1065!AA:AB)} -> 9 | L82: 3个月以上 | M82: 4、慢偏 | N82: 1 | O82: =_xlfn.XLOOKUP(P82,匹配表1065!U:U,匹配表1065!T:T) -> HO00000940 | P82: 常州市第一人民医院 | Q82: 薛海翔 | R82: =_xlfn.XLOOKUP(Q82,匹配表1065!L:L,匹配表1065!O:O) -> C | S82: =IFERROR(_xlfn.XLOOKUP(Q82,匹配表1065!AI:AI,匹配表1065!AJ:AJ),"绿标") -> 红标 | T82: {=_xlfn.XLOOKUP(Q82,匹配表1065!L:L,匹配表1065!M:N)} -> 眩晕 | U82: 耳鼻喉科 | V82: 小于4次（低频） | W82: =_xlfn.XLOOKUP(M82,匹配表1065!D:D,匹配表1065!F:F)*N82 -> 16
A83: 4月 | B83: 46114 | C83: =MONTH(B83)&TEXT(WEEKNUM(B83,2)-WEEKNUM(B83+1-DAY(B83),2)+1,"月第0周") -> 4月第1周 | D83: 4月第1周 | E83: =D83&"--"&"周"&WEEKDAY(B83,2) -> 4月第1周--周4 | F83: 钟君珊 | G83: 郑家成 | H83: =_xlfn.XLOOKUP(O83,匹配表1065!T:T,匹配表1065!W:W) -> 南京市 | I83: =_xlfn.XLOOKUP(O83,匹配表1065!T:T,匹配表1065!X:X) -> PME2005 | J83: 徐燕 | K83: {=_xlfn.XLOOKUP(J83,匹配表1065!Y:Y,匹配表1065!AA:AB)} -> 3 | L83: 3个月以上 | M83: 3、VM | N83: 1 | O83: =_xlfn.XLOOKUP(P83,匹配表1065!U:U,匹配表1065!T:T) -> HO00000975 | P83: 南京脑科医院 | Q83: 胡秀秀 | R83: =_xlfn.XLOOKUP(Q83,匹配表1065!L:L,匹配表1065!O:O) -> B | S83: =IFERROR(_xlfn.XLOOKUP(Q83,匹配表1065!AI:AI,匹配表1065!AJ:AJ),"绿标") -> 绿标 | T83: {=_xlfn.XLOOKUP(Q83,匹配表1065!L:L,匹配表1065!M:N)} -> 脑血管 | U83: 神经内科 | V83: 4-7次（中频） | W83: =_xlfn.XLOOKUP(M83,匹配表1065!D:D,匹配表1065!F:F)*N83 -> 12
A84: 4月 | B84: 46114 | C84: =MONTH(B84)&TEXT(WEEKNUM(B84,2)-WEEKNUM(B84+1-DAY(B84),2)+1,"月第0周") -> 4月第1周 | D84: 4月第1周 | E84: =D84&"--"&"周"&WEEKDAY(B84,2) -> 4月第1周--周4 | F84: 钟君珊 | G84: 卜先峰 | H84: =_xlfn.XLOOKUP(O84,匹配表1065!T:T,匹配表1065!W:W) -> 合肥市 | I84: =_xlfn.XLOOKUP(O84,匹配表1065!T:T,匹配表1065!X:X) -> PME2007 | J84: 杨胜运 | K84: {=_xlfn.XLOOKUP(J84,匹配表1065!Y:Y,匹配表1065!AA:AB)} -> 9 | L84: 3个月以上 | M84: 1、中频 | N84: 1 | O84: =_xlfn.XLOOKUP(P84,匹配表1065!U:U,匹配表1065!T:T) -> HO00000001 | P84: 安徽医科大学第一附属医院 | Q84: 章娟娟 | R84: =_xlfn.XLOOKUP(Q84,匹配表1065!L:L,匹配表1065!O:O) -> A | S84: =IFERROR(_xlfn.XLOOKUP(Q84,匹配表1065!AI:AI,匹配表1065!AJ:AJ),"绿标") -> 绿标 | T84: {=_xlfn.XLOOKUP(Q84,匹配表1065!L:L,匹配表1065!M:N)} -> 头痛 | U84: 神经内科 | V84: 小于4次（低频） | W84: =_xlfn.XLOOKUP(M84,匹配表1065!D:D,匹配表1065!F:F)*N84 -> 4
A85: 4月 | B85: 46114 | C85: =MONTH(B85)&TEXT(WEEKNUM(B85,2)-WEEKNUM(B85+1-DAY(B85),2)+1,"月第0周") -> 4月第1周 | D85: 4月第1周 | E85: =D85&"--"&"周"&WEEKDAY(B85,2) -> 4月第1周--周4 | F85: 钟君珊 | G85: 卜先峰 | H85: =_xlfn.XLOOKUP(O85,匹配表1065!T:T,匹配表1065!W:W) -> 合肥市 | I85: =_xlfn.XLOOKUP(O85,匹配表1065!T:T,匹配表1065!X:X) -> PME2007 | J85: 杨胜运 | K85: {=_xlfn.XLOOKUP(J85,匹配表1065!Y:Y,匹配表1065!AA:AB)} -> 9 | L85: 3个月以上 | M85: 4、慢偏 | N85: 1 | O85: =_xlfn.XLOOKUP(P85,匹配表1065!U:U,匹配表1065!T:T) -> HO00000001 | P85: 安徽医科大学第一附属医院 | Q85: 汪敬业 | R85: =_xlfn.XLOOKUP(Q85,匹配表1065!L:L,匹配表1065!O:O) -> C | S85: =IFERROR(_xlfn.XLOOKUP(Q85,匹配表1065!AI:AI,匹配表1065!AJ:AJ),"绿标") -> 红标 | T85: {=_xlfn.XLOOKUP(Q85,匹配表1065!L:L,匹配表1065!M:N)} -> 眩晕 | U85: 神经内科 | V85: 大于8次（高频） | W85: =_xlfn.XLOOKUP(M85,匹配表1065!D:D,匹配表1065!F:F)*N85 -> 16
A86: 4月 | B86: 46114 | C86: =MONTH(B86)&TEXT(WEEKNUM(B86,2)-WEEKNUM(B86+1-DAY(B86),2)+1,"月第0周") -> 4月第1周 | D86: 4月第1周 | E86: =D86&"--"&"周"&WEEKDAY(B86,2) -> 4月第1周--周4 | F86: 钟君珊 | G86: 卜先峰 | H86: =_xlfn.XLOOKUP(O86,匹配表1065!T:T,匹配表1065!W:W) -> 合肥市 | I86: =_xlfn.XLOOKUP(O86,匹配表1065!T:T,匹配表1065!X:X) -> PME2047 | J86: 洪剑 | K86: {=_xlfn.XLOOKUP(J86,匹配表1065!Y:Y,匹配表1065!AA:AB)} -> 2 | L86: 3个月以内 | M86: 1、中频 | N86: 1 | O86: =_xlfn.XLOOKUP(P86,匹配表1065!U:U,匹配表1065!T:T) -> HO00000005 | P86: 安徽省立医院 | Q86: 桂韦 | R86: =_xlfn.XLOOKUP(Q86,匹配表1065!L:L,匹配表1065!O:O) -> A | S86: =IFERROR(_xlfn.XLOOKUP(Q86,匹配表1065!AI:AI,匹配表1065!AJ:AJ),"绿标") -> 黑标 | T86: {=_xlfn.XLOOKUP(Q86,匹配表1065!L:L,匹配表1065!M:N)} -> 头痛 | U86: 神经内科 | V86: 小于4次（低频） | W86: =_xlfn.XLOOKUP(M86,匹配表1065!D:D,匹配表1065!F:F)*N86 -> 4
A87: 4月 | B87: 46114 | C87: =MONTH(B87)&TEXT(WEEKNUM(B87,2)-WEEKNUM(B87+1-DAY(B87),2)+1,"月第0周") -> 4月第1周 | D87: 4月第1周 | E87: =D87&"--"&"周"&WEEKDAY(B87,2) -> 4月第1周--周4 | F87: 钟君珊 | G87: 卜先峰 | H87: =_xlfn.XLOOKUP(O87,匹配表1065!T:T,匹配表1065!W:W) -> 合肥市 | I87: =_xlfn.XLOOKUP(O87,匹配表1065!T:T,匹配表1065!X:X) -> PME2047 | J87: 洪剑 | K87: {=_xlfn.XLOOKUP(J87,匹配表1065!Y:Y,匹配表1065!AA:AB)} -> 2 | L87: 3个月以内 | M87: 1、中频 | N87: 1 | O87: =_xlfn.XLOOKUP(P87,匹配表1065!U:U,匹配表1065!T:T) -> HO00000005 | P87: 安徽省立医院 | Q87: 桂韦 | R87: =_xlfn.XLOOKUP(Q87,匹配表1065!L:L,匹配表1065!O:O) -> A | S87: =IFERROR(_xlfn.XLOOKUP(Q87,匹配表1065!AI:AI,匹配表1065!AJ:AJ),"绿标") -> 黑标 | T87: {=_xlfn.XLOOKUP(Q87,匹配表1065!L:L,匹配表1065!M:N)} -> 头痛 | U87: 神经内科 | V87: 小于4次（低频） | W87: =_xlfn.XLOOKUP(M87,匹配表1065!D:D,匹配表1065!F:F)*N87 -> 4
A88: 4月 | B88: 46114 | C88: =MONTH(B88)&TEXT(WEEKNUM(B88,2)-WEEKNUM(B88+1-DAY(B88),2)+1,"月第0周") -> 4月第1周 | D88: 4月第1周 | E88: =D88&"--"&"周"&WEEKDAY(B88,2) -> 4月第1周--周4 | F88: 钟君珊 | G88: 孟鈃 | H88: =_xlfn.XLOOKUP(O88,匹配表1065!T:T,匹配表1065!W:W) -> 南京市 | I88: =_xlfn.XLOOKUP(O88,匹配表1065!T:T,匹配表1065!X:X) -> PME2001 | J88: 王方方 | K88: {=_xlfn.XLOOKUP(J88,匹配表1065!Y:Y,匹配表1065!AA:AB)} -> 31 | L88: 3个月以上 | M88: 3、VM | N88: 3 | O88: =_xlfn.XLOOKUP(P88,匹配表1065!U:U,匹配表1065!T:T) -> HO00000958 | P88: 江苏省人民医院 | Q88: 王登元 | R88: =_xlfn.XLOOKUP(Q88,匹配表1065!L:L,匹配表1065!O:O) -> C | S88: =IFERROR(_xlfn.XLOOKUP(Q88,匹配表1065!AI:AI,匹配表1065!AJ:AJ),"绿标") -> 红标 | T88: {=_xlfn.XLOOKUP(Q88,匹配表1065!L:L,匹配表1065!M:N)} -> 眩晕 | U88: 耳鼻喉科 | V88: 焦虑抑郁共病 | W88: =_xlfn.XLOOKUP(M88,匹配表1065!D:D,匹配表1065!F:F)*N88 -> 36
A89: 4月 | B89: 46114 | C89: =MONTH(B89)&TEXT(WEEKNUM(B89,2)-WEEKNUM(B89+1-DAY(B89),2)+1,"月第0周") -> 4月第1周 | D89: 4月第1周 | E89: =D89&"--"&"周"&WEEKDAY(B89,2) -> 4月第1周--周4 | F89: 钟君珊 | G89: 孟鈃 | H89: =_xlfn.XLOOKUP(O89,匹配表1065!T:T,匹配表1065!W:W) -> 南京市 | I89: =_xlfn.XLOOKUP(O89,匹配表1065!T:T,匹配表1065!X:X) -> PME2001 | J89: 王方方 | K89: {=_xlfn.XLOOKUP(J89,匹配表1065!Y:Y,匹配表1065!AA:AB)} -> 31 | L89: 3个月以上 | M89: 1、中频 | N89: 1 | O89: =_xlfn.XLOOKUP(P89,匹配表1065!U:U,匹配表1065!T:T) -> HO00000958 | P89: 江苏省人民医院 | Q89: 赵晓埝 | R89: =_xlfn.XLOOKUP(Q89,匹配表1065!L:L,匹配表1065!O:O) -> C | S89: =IFERROR(_xlfn.XLOOKUP(Q89,匹配表1065!AI:AI,匹配表1065!AJ:AJ),"绿标") -> 绿标 | T89: {=_xlfn.XLOOKUP(Q89,匹配表1065!L:L,匹配表1065!M:N)} -> 眩晕 | U89: 耳鼻喉科 | V89: 焦虑抑郁共病 | W89: =_xlfn.XLOOKUP(M89,匹配表1065!D:D,匹配表1065!F:F)*N89 -> 4
A90: 4月 | B90: 46114 | C90: =MONTH(B90)&TEXT(WEEKNUM(B90,2)-WEEKNUM(B90+1-DAY(B90),2)+1,"月第0周") -> 4月第1周 | D90: 4月第1周 | E90: =D90&"--"&"周"&WEEKDAY(B90,2) -> 4月第1周--周4 | F90: 钟君珊 | G90: 孟鈃 | H90: =_xlfn.XLOOKUP(O90,匹配表1065!T:T,匹配表1065!W:W) -> 南京市 | I90: =_xlfn.XLOOKUP(O90,匹配表1065!T:T,匹配表1065!X:X) -> PME2001 | J90: 王方方 | K90: {=_xlfn.XLOOKUP(J90,匹配表1065!Y:Y,匹配表1065!AA:AB)} -> 31 | L90: 3个月以上 | M90: 2、高频 | N90: 1 | O90: =_xlfn.XLOOKUP(P90,匹配表1065!U:U,匹配表1065!T:T) -> HO00000958 | P90: 江苏省人民医院 | Q90: 顾萍 | R90: =_xlfn.XLOOKUP(Q90,匹配表1065!L:L,匹配表1065!O:O) -> A | S90: =IFERROR(_xlfn.XLOOKUP(Q90,匹配表1065!AI:AI,匹配表1065!AJ:AJ),"绿标") -> 红标 | T90: {=_xlfn.XLOOKUP(Q90,匹配表1065!L:L,匹配表1065!M:N)} -> 头痛 | U90: 神经内科 | V90: 小于4次（低频） | W90: =_xlfn.XLOOKUP(M90,匹配表1065!D:D,匹配表1065!F:F)*N90 -> 8
A91: 4月 | B91: 46114 | C91: =MONTH(B91)&TEXT(WEEKNUM(B91,2)-WEEKNUM(B91+1-DAY(B91),2)+1,"月第0周") -> 4月第1周 | D91: 4月第1周 | E91: =D91&"--"&"周"&WEEKDAY(B91,2) -> 4月第1周--周4 | F91: 钟君珊 | G91: 孟鈃 | H91: =_xlfn.XLOOKUP(O91,匹配表1065!T:T,匹配表1065!W:W) -> 淮安市 | I91: =_xlfn.XLOOKUP(O91,匹配表1065!T:T,匹配表1065!X:X) -> PME2041 | J91: 徐自豪 | K91: {=_xlfn.XLOOKUP(J91,匹配表1065!Y:Y,匹配表1065!AA:AB)} -> 5 | L91: 3个月以上 | M91: 1、中频 | N91: 1 | O91: =_xlfn.XLOOKUP(P91,匹配表1065!U:U,匹配表1065!T:T) -> HO00000992 | P91: 淮安市第一人民医院 | Q91: 蔡诗昆 | R91: =_xlfn.XLOOKUP(Q91,匹配表1065!L:L,匹配表1065!O:O) -> D | S91: =IFERROR(_xlfn.XLOOKUP(Q91,匹配表1065!AI:AI,匹配表1065!AJ:AJ),"绿标") -> 绿标 | T91: {=_xlfn.XLOOKUP(Q91,匹配表1065!L:L,匹配表1065!M:N)} -> 眩晕 | U91: 神经内科 | V91: 小于4次（低频） | W91: =_xlfn.XLOOKUP(M91,匹配表1065!D:D,匹配表1065!F:F)*N91 -> 4
... A154: 4月 | B154: 46115 | C154: =MONTH(B154)&TEXT(WEEKNUM(B154,2)-WEEKNUM(B154+1-DAY(B154),2)+1,"月第0周") -> 4月第1周 | D154: 4月第1周 | E154: =D154&"--"&"周"&WEEKDAY(B154,2) -> 4月第1周--周5 | F154: 钟君珊 | G154: 郑家成 | H154: =_xlfn.XLOOKUP(O154,匹配表1065!T:T,匹配表1065!W:W) -> 扬州市 | I154: =_xlfn.XLOOKUP(O154,匹配表1065!T:T,匹配表1065!X:X) -> PME2012 | J154: 高佳怡 | K154: {=_xlfn.XLOOKUP(J154,匹配表1065!Y:Y,匹配表1065!AA:AB)} -> 13 | L154: 3个月以上 | M154: 2、高频 | N154: 1 | O154: =_xlfn.XLOOKUP(P154,匹配表1065!U:U,匹配表1065!T:T) -> HO00000968 | P154: 江苏省苏北人民医院 | Q154: 刘筱洁 | R154: =_xlfn.XLOOKUP(Q154,匹配表1065!L:L,匹配表1065!O:O) -> B | S154: =IFERROR(_xlfn.XLOOKUP(Q154,匹配表1065!AI:AI,匹配表1065!AJ:AJ),"绿标") -> 绿标 | T154: {=_xlfn.XLOOKUP(Q154,匹配表1065!L:L,匹配表1065!M:N)} -> 脑血管 | U154: 神经内科 | V154: 4-7次（中频） | W154: =_xlfn.XLOOKUP(M154,匹配表1065!D:D,匹配表1065!F:F)*N154 -> 8
A155: 4月 | B155: 46115 | C155: =MONTH(B155)&TEXT(WEEKNUM(B155,2)-WEEKNUM(B155+1-DAY(B155),2)+1,"月第0周") -> 4月第1周 | D155: 4月第1周 | E155: =D155&"--"&"周"&WEEKDAY(B155,2) -> 4月第1周--周5 | F155: 钟君珊 | G155: 郑家成 | H155: =_xlfn.XLOOKUP(O155,匹配表1065!T:T,匹配表1065!W:W) -> 南京市 | I155: =_xlfn.XLOOKUP(O155,匹配表1065!T:T,匹配表1065!X:X) -> PME2040 | J155: 王玉婷 | K155: {=_xlfn.XLOOKUP(J155,匹配表1065!Y:Y,匹配表1065!AA:AB)} -> #N/A | M155: 2、高频 | N155: 1 | O155: =_xlfn.XLOOKUP(P155,匹配表1065!U:U,匹配表1065!T:T) -> HO00000966 | P155: 南京医科大学第二附属医院 | Q155: 张鹏 | R155: =_xlfn.XLOOKUP(Q155,匹配表1065!L:L,匹配表1065!O:O) -> A | S155: =IFERROR(_xlfn.XLOOKUP(Q155,匹配表1065!AI:AI,匹配表1065!AJ:AJ),"绿标") -> 绿标 | T155: {=_xlfn.XLOOKUP(Q155,匹配表1065!L:L,匹配表1065!M:N)} -> 头痛 | U155: 神经内科 | V155: 4-7次（中频） | W155: =_xlfn.XLOOKUP(M155,匹配表1065!D:D,匹配表1065!F:F)*N155 -> 8
A156: 4月 | B156: 46115 | C156: =MONTH(B156)&TEXT(WEEKNUM(B156,2)-WEEKNUM(B156+1-DAY(B156),2)+1,"月第0周") -> 4月第1周 | D156: 4月第1周 | E156: =D156&"--"&"周"&WEEKDAY(B156,2) -> 4月第1周--周5 | F156: 钟君珊 | G156: 孟鈃 | H156: =_xlfn.XLOOKUP(O156,匹配表1065!T:T,匹配表1065!W:W) -> 南京市 | I156: =_xlfn.XLOOKUP(O156,匹配表1065!T:T,匹配表1065!X:X) -> PME2001 | J156: 王方方 | K156: {=_xlfn.XLOOKUP(J156,匹配表1065!Y:Y,匹配表1065!AA:AB)} -> 31 | L156: 3个月以上 | M156: 3、VM | N156: 3 | O156: =_xlfn.XLOOKUP(P156,匹配表1065!U:U,匹配表1065!T:T) -> HO00000958 | P156: 江苏省人民医院 | Q156: 顾萍 | R156: =_xlfn.XLOOKUP(Q156,匹配表1065!L:L,匹配表1065!O:O) -> A | S156: =IFERROR(_xlfn.XLOOKUP(Q156,匹配表1065!AI:AI,匹配表1065!AJ:AJ),"绿标") -> 红标 | T156: {=_xlfn.XLOOKUP(Q156,匹配表1065!L:L,匹配表1065!M:N)} -> 头痛 | U156: 神经内科 | V156: 大于8次（高频） | W156: =_xlfn.XLOOKUP(M156,匹配表1065!D:D,匹配表1065!F:F)*N156 -> 36
...

Sheet 匹配表1065
A1: 匹配 | D1: 患者画像 | E1: 对应 | F1: 值 | H1: DM | I1: MICS | J1: 医院Code | K1: 医院 | L1: 客户 | M1: 亚专业矫正 | N1: 科室矫正 | O1: 客户类型矫正 | R1: 地区名称 | S1: DM姓名 | T1: 医院代码 | U1: 医院名称 | V1: 省 | W1: 城市 | X1: 岗位英文名称 | Y1: MICS姓名 | Z1: 入职时间 | AA1: 工作月份 | AB1: 入职划分 | AF1: DM | AG1: MICS | AH1: 医院名称 | AI1: 客户名 | AJ1: 标类 | AM1: 患者类型
A2: 1M | B2: 4 | D2: 0、低频 | E2: 1S | F2: 1 | H2: 孟鈃 | I2: 王方方 | J2: HO00000958 | K2: 江苏省人民医院 | L2: 王登元 | M2: 眩晕 | N2: 耳鼻喉科 | O2: C | R2: DME2001 | S2: 郑家成 | T2: HO00000960 | U2: 中国人民解放军东部战区总医院秦淮医疗区 | V2: 江苏 | W2: 南京市 | X2: PME2004 | Y2: 杨帆 | Z2: 45901 | AA2: =DATEDIF(Z2,TODAY(),"M") -> 11 | AB2: =LOOKUP(AA2,{0,1,3},{"1个月以内","3个月以内","3个月以上"}) -> 3个月以上 | AF2: 张鑫 | AG2: 冯雅琪 | AH2: 青岛市中医医院 | AI2: 于永鹏 | AJ2: 红标 | AM2: 4-7次（中频）
A3: 2M | B3: 8 | D3: 1、中频 | E3: 1M | F3: 4 | H3: 孟鈃 | I3: 芦晓辉 | J3: HO00000958 | K3: 江苏省人民医院 | L3: 张克忠 | M3: 其他 | N3: 神经内科 | O3: B | R3: DME2001 | S3: 郑家成 | T3: HO00000972 | U3: 中国人民解放军东部战区总医院 | V3: 江苏 | W3: 南京市 | X3: PME2004 | Y3: 杨帆 | Z3: 45901 | AA3: =DATEDIF(Z3,TODAY(),"M") -> 11 | AB3: =LOOKUP(AA3,{0,1,3},{"1个月以内","3个月以内","3个月以上"}) -> 3个月以上 | AF3: 张鑫 | AG3: 冯雅琪 | AH3: 青岛市中医医院 | AI3: 陈晓宇 | AJ3: 红标 | AM3: 大于8次（高频）
A4: 3M | B4: 12 | D4: 2、高频 | E4: 2M | F4: 8 | H4: 孟鈃 | I4: 徐自豪 | J4: HO00000992 | K4: 淮安市第一人民医院 | L4: 蔡诗昆 | M4: 眩晕 | N4: 神经内科 | O4: D | R4: DME2001 | S4: 郑家成 | T4: HO00000974 | U4: 南京梅山医院有限责任公司 | V4: 江苏 | W4: 南京市 | X4: PME2004 | Y4: 杨帆 | Z4: 45901 | AA4: =DATEDIF(Z4,TODAY(),"M") -> 11 | AB4: =LOOKUP(AA4,{0,1,3},{"1个月以内","3个月以内","3个月以上"}) -> 3个月以上 | AF4: 张鑫 | AG4: 冯雅琪 | AH4: 青岛市中医医院 | AI4: 葛洪洲 | AJ4: 红标 | AM4: 小于4次（低频）
A5: 4M | B5: 16 | D5: 3、VM | E5: 3M | F5: 12 | H5: 孟鈃 | I5: 章智程 | J5: HO00000989 | K5: 徐州医科大学附属医院 | L5: 时宏娟 | M5: 头痛 | N5: 神经内科 | O5: A | R5: DME2001 | S5: 郑家成 | T5: HO00000976 | U5: 中国人民解放军东部战区空军医院 | V5: 江苏 | W5: 南京市 | X5: PME2004 | Y5: 杨帆 | Z5: 45901 | AA5: =DATEDIF(Z5,TODAY(),"M") -> 11 | AB5: =LOOKUP(AA5,{0,1,3},{"1个月以内","3个月以内","3个月以上"}) -> 3个月以上 | AF5: 张鑫 | AG5: 冯雅琪 | AH5: 青岛市中医医院 | AI5: 马晓维 | AJ5: 绿标 | AM5: VM
A6: 5M | B6: 20 | D6: 4、慢偏 | E6: 4M | F6: 16 | H6: 孟鈃 | I6: 芦晓辉 | J6: HO00000958 | K6: 江苏省人民医院 | L6: 燕兰云 | M6: 头痛 | N6: 神经内科 | O6: A | R6: DME2001 | S6: 郑家成 | T6: HO00001017 | U6: 南京市江宁医院 | V6: 江苏 | W6: 南京市 | X6: PME2004 | Y6: 杨帆 | Z6: 45901 | AA6: =DATEDIF(Z6,TODAY(),"M") -> 11 | AB6: =LOOKUP(AA6,{0,1,3},{"1个月以内","3个月以内","3个月以上"}) -> 3个月以上 | AF6: 张鑫 | AG6: 冯雅琪 | AH6: 青岛市中医医院 | AI6: 游会增 | AJ6: 绿标 | AM6: CM/MOH
A7: 6M | B7: 24 | D7: 5、MOH | E7: 5M | F7: 20 | H7: 孟鈃 | I7: 芦晓辉 | J7: HO00000958 | K7: 江苏省人民医院 | L7: 李耀 | M7: 脑血管 | N7: 神经内科 | O7: B | R7: DME2001 | S7: 郑家成 | T7: HO00016757 | U7: 南京市浦口区中心医院 | V7: 江苏 | W7: 南京市 | X7: PME2004 | Y7: 杨帆 | Z7: 45901 | AA7: =DATEDIF(Z7,TODAY(),"M") -> 11 | AB7: =LOOKUP(AA7,{0,1,3},{"1个月以内","3个月以内","3个月以上"}) -> 3个月以上 | AF7: 张鑫 | AG7: 冯雅琪 | AH7: 青岛市中医医院 | AI7: 韩萍 | AJ7: 黑标 | AM7: 焦虑抑郁共病
A8: 7M | B8: 28 | D8: 6、其他 | E8: 6M | F8: 24 | H8: 孟鈃 | I8: 芦晓辉 | J8: HO00000958 | K8: 江苏省人民医院 | L8: 金善泉 | M8: 头痛 | N8: 神经内科 | O8: A | R8: DME2001 | S8: 郑家成 | T8: HO00043198 | U8: 南京同仁医院 | V8: 江苏 | W8: 南京市 | X8: PME2004 | Y8: 杨帆 | Z8: 45901 | AA8: =DATEDIF(Z8,TODAY(),"M") -> 11 | AB8: =LOOKUP(AA8,{0,1,3},{"1个月以内","3个月以内","3个月以上"}) -> 3个月以上 | AF8: 张鑫 | AG8: 冯雅琪 | AH8: 青岛市中医医院 | AI8: 唐咏春 | AJ8: 黑标 | AM8: 月经偏
A9: 8M | B9: 32 | H9: 孟鈃 | I9: 黄燕儿 | J9: HO00001004 | K9: 连云港市第一人民医院 | L9: 孙永安 | M9: 脑血管 | N9: 神经内科 | O9: B | R9: DME2001 | S9: 郑家成 | T9: HO00260546 | U9: 南京一民医院有限公司 | V9: 江苏 | W9: 南京市 | X9: PME2004 | Y9: 杨帆 | Z9: 45901 | AA9: =DATEDIF(Z9,TODAY(),"M") -> 11 | AB9: =LOOKUP(AA9,{0,1,3},{"1个月以内","3个月以内","3个月以上"}) -> 3个月以上 | AF9: 张鑫 | AG9: 冯雅琪 | AH9: 青岛市中医医院 | AI9: 于春蕾 | AJ9: 黑标 | AM9: 先兆/脑血管风险
A10: 9M | B10: 36 | H10: 孟鈃 | I10: 罗世懿 | J10: HO00000964 | K10: 南京鼓楼医院 | L10: 张清秀 | M10: 头痛 | N10: 神经内科 | O10: A | R10: DME2001 | S10: 郑家成 | T10: HO00392428 | U10: 南京市江宁医院湖山路院区 | V10: 江苏 | W10: 南京市 | X10: PME2004 | Y10: 杨帆 | Z10: 45901 | AA10: =DATEDIF(Z10,TODAY(),"M") -> 11 | AB10: =LOOKUP(AA10,{0,1,3},{"1个月以内","3个月以内","3个月以上"}) -> 3个月以上 | AF10: 张鑫 | AG10: 冯雅琪 | AH10: 青岛市中医医院 | AI10: 李彬 | AJ10: 黑标 | AM10: 其他
A11: 10M | B11: 40 | H11: 孟鈃 | I11: 罗世懿 | J11: HO00000964 | K11: 南京鼓楼医院 | L11: 韩影 | M11: 疼痛 | N11: 疼痛科 | O11: D | R11: DME2001 | S11: 郑家成 | T11: HO00000961 | U11: 江苏省肿瘤防治研究所 | V11: 江苏 | W11: 南京市 | X11: PME2005 | Y11: 徐燕 | Z11: 46160 | AA11: =DATEDIF(Z11,TODAY(),"M") -> 3 | AB11: =LOOKUP(AA11,{0,1,3},{"1个月以内","3个月以内","3个月以上"}) -> 3个月以上 | AF11: 张鑫 | AG11: 冯雅琪 | AH11: 青岛市中医医院 | AI11: 朱晓宁 | AJ11: 绿标
A12: 1S | B12: 1 | H12: 卜先峰 | I12: 杨胜运 | J12: HO00000001 | K12: 安徽医科大学第一附属医院 | L12: 汪敬业 | M12: 眩晕 | N12: 神经内科 | O12: C | R12: DME2001 | S12: 郑家成 | T12: HO00000973 | U12: 南京市胸科医院 | V12: 江苏 | W12: 南京市 | X12: PME2005 | Y12: 徐燕 | Z12: 46160 | AA12: =DATEDIF(Z12,TODAY(),"M") -> 3 | AB12: =LOOKUP(AA12,{0,1,3},{"1个月以内","3个月以内","3个月以上"}) -> 3个月以上 | AF12: 张鑫 | AG12: 冯雅琪 | AH12: 青岛大学附属医院 | AI12: 刘敏 | AJ12: 红标
A13: 2S | B13: 2 | H13: 卜先峰 | I13: 杨胜运 | J13: HO00000001 | K13: 安徽医科大学第一附属医院 | L13: 张龙 | M13: 脑血管 | N13: 神经内科 | O13: B | R13: DME2001 | S13: 郑家成 | T13: HO00000975 | U13: 南京脑科医院 | V13: 江苏 | W13: 南京市 | X13: PME2005 | Y13: 徐燕 | Z13: 46160 | AA13: =DATEDIF(Z13,TODAY(),"M") -> 3 | AB13: =LOOKUP(AA13,{0,1,3},{"1个月以内","3个月以内","3个月以上"}) -> 3个月以上 | AF13: 张鑫 | AG13: 冯雅琪 | AH13: 青岛大学附属医院 | AI13: 李红云 | AJ13: 红标
A14: 3S | B14: 3 | H14: 卜先峰 | I14: 杨胜运 | J14: HO00000001 | K14: 安徽医科大学第一附属医院 | L14: 章娟娟 | M14: 头痛 | N14: 神经内科 | O14: A | R14: DME2001 | S14: 郑家成 | T14: HO00098805 | U14: 南京仁品耳鼻喉专科医院 | V14: 江苏 | W14: 南京市 | X14: PME2005 | Y14: 徐燕 | Z14: 46160 | AA14: =DATEDIF(Z14,TODAY(),"M") -> 3 | AB14: =LOOKUP(AA14,{0,1,3},{"1个月以内","3个月以内","3个月以上"}) -> 3个月以上 | AF14: 张鑫 | AG14: 冯雅琪 | AH14: 青岛大学附属医院 | AI14: 赵仁亮 | AJ14: 黑标
A15: 4S | B15: 4 | H15: 卜先峰 | I15: 许恺丽 | J15: HO00002956 | K15: 安徽医科大学第一附属医院南区 | L15: 高建国 | M15: 脑血管 | N15: 神经内科 | O15: B | R15: DME2001 | S15: 郑家成 | T15: HO00137885 | U15: 南京市建邺区南湖社区卫生服务中心 | V15: 江苏 | W15: 南京市 | X15: PME2005 | Y15: 徐燕 | Z15: 46160 | AA15: =DATEDIF(Z15,TODAY(),"M") -> 3 | AB15: =LOOKUP(AA15,{0,1,3},{"1个月以内","3个月以内","3个月以上"}) -> 3个月以上 | AF15: 张鑫 | AG15: 冯雅琪 | AH15: 青岛大学附属医院 | AI15: 王乃东 | AJ15: 黑标
A16: 5S | B16: 5 | H16: 张鑫 | I16: 陈彩虹 | J16: HO00072793 | K16: 青岛市西海岸医院 | L16: 张亮 | M16: 头痛 | N16: 神经内科 | O16: A | R16: DME2001 | S16: 郑家成 | T16: HO00140094 | U16: 南京医科大学附属逸夫医院 | V16: 江苏 | W16: 南京市 | X16: PME2005 | Y16: 徐燕 | Z16: 46160 | AA16: =DATEDIF(Z16,TODAY(),"M") -> 3 | AB16: =LOOKUP(AA16,{0,1,3},{"1个月以内","3个月以内","3个月以上"}) -> 3个月以上 | AF16: 张鑫 | AG16: 冯雅琪 | AH16: 青岛大学附属医院 | AI16: 张晓恒 | AJ16: 红标
A17: 6S | B17: 6 | H17: 张鑫 | I17: 陈彩虹 | J17: HO00072793 | K17: 青岛市西海岸医院 | L17: 李宏 | M17: 眩晕 | N17: 神经内科 | O17: C | R17: DME2001 | S17: 郑家成 | T17: HO00157456 | U17: 南京圆心门诊部有限公司 | V17: 江苏 | W17: 南京市 | X17: PME2005 | Y17: 徐燕 | Z17: 46160 | AA17: =DATEDIF(Z17,TODAY(),"M") -> 3 | AB17: =LOOKUP(AA17,{0,1,3},{"1个月以内","3个月以内","3个月以上"}) -> 3个月以上 | AF17: 张鑫 | AG17: 冯雅琪 | AH17: 青岛大学附属医院 | AI17: 纪彩丽 | AJ17: 绿标
A18: 7S | B18: 7 | H18: 张鑫 | I18: 陈本相 | J18: HO00001481 | K18: 青岛市妇女儿童医院 | L18: 梁冰 | M18: 头痛 | N18: 神经内科 | O18: A | R18: DME2001 | S18: 郑家成 | T18: HO00402266 | U18: 南京健华康复医院有限公司 | V18: 江苏 | W18: 南京市 | X18: PME2005 | Y18: 徐燕 | Z18: 46160 | AA18: =DATEDIF(Z18,TODAY(),"M") -> 3 | AB18: =LOOKUP(AA18,{0,1,3},{"1个月以内","3个月以内","3个月以上"}) -> 3个月以上 | AF18: 张鑫 | AG18: 冯雅琪 | AH18: 青岛大学附属医院 | AI18: 王琨 | AJ18: 红标
A19: 8S | B19: 8 | H19: 张鑫 | I19: 陈本相 | J19: HO00273985 | K19: 青岛大学附属医院(平度院区) | L19: 李鑫 | M19: 脑血管 | N19: 神经内科 | O19: B | R19: DME2001 | S19: 郑家成 | T19: HO00000959 | U19: 南京市第一医院 | V19: 江苏 | W19: 南京市 | X19: PME2006 | Y19: 孙娟 | Z19: 45803 | AA19: =DATEDIF(Z19,TODAY(),"M") -> 15 | AB19: =LOOKUP(AA19,{0,1,3},{"1个月以内","3个月以内","3个月以上"}) -> 3个月以上 | AF19: 张鑫 | AG19: 冯雅琪 | AH19: 青岛大学附属医院 | AI19: 王源 | AJ19: 黑标
A20: 9S | B20: 9 | H20: 张鑫 | I20: 鲁景霄 | J20: HO00024398 | K20: 淄博一四八医院 | L20: 李修文 | M20: 眩晕 | N20: 神经内科 | O20: C | R20: DME2001 | S20: 郑家成 | T20: HO00000965 | U20: 东南大学附属中大医院 | V20: 江苏 | W20: 南京市 | X20: PME2006 | Y20: 孙娟 | Z20: 45803 | AA20: =DATEDIF(Z20,TODAY(),"M") -> 15 | AB20: =LOOKUP(AA20,{0,1,3},{"1个月以内","3个月以内","3个月以上"}) -> 3个月以上 | AF20: 张鑫 | AG20: 冯雅琪 | AH20: 青岛大学附属医院 | AI20: 赵洪芹 | AJ20: 黑标
A21: 10S | B21: 10 | H21: 张鑫 | I21: 张鑫 | J21: HO00139638 | K21: 山东阳光融和医院有限责任公司 | L21: 逄锦晶 | M21: 眩晕 | N21: 神经内科 | O21: C | R21: DME2001 | S21: 郑家成 | T21: HO00000997 | U21: 南京市红十字医院 | V21: 江苏 | W21: 南京市 | X21: PME2006 | Y21: 孙娟 | Z21: 45803 | AA21: =DATEDIF(Z21,TODAY(),"M") -> 15 | AB21: =LOOKUP(AA21,{0,1,3},{"1个月以内","3个月以内","3个月以上"}) -> 3个月以上 | AF21: 张鑫 | AG21: 冯雅琪 | AH21: 青岛大学附属医院 | AI21: 王海萍 | AJ21: 绿标
H22: 张鑫 | I22: 张鑫 | J22: HO00001466 | K22: 诸城市人民医院 | L22: 房春燕 | M22: 眩晕 | N22: 神经内科 | O22: C | R22: DME2001 | S22: 郑家成 | T22: HO00001002 | U22: 南京市第一医院河西院区 | V22: 江苏 | W22: 南京市 | X22: PME2006 | Y22: 孙娟 | Z22: 45803 | AA22: =DATEDIF(Z22,TODAY(),"M") -> 15 | AB22: =LOOKUP(AA22,{0,1,3},{"1个月以内","3个月以内","3个月以上"}) -> 3个月以上 | AF22: 张鑫 | AG22: 冯雅琪 | AH22: 青岛大学附属医院 | AI22: 杨绍楠 | AJ22: 绿标
H23: 张鑫 | I23: 张鑫 | J23: HO00001496 | K23: 山东第二医科大学附属医院 | L23: 于新军 | M23: 眩晕 | N23: 神经内科 | O23: C | R23: DME2001 | S23: 郑家成 | T23: HO00016614 | U23: 南京市溧水区人民医院 | V23: 江苏 | W23: 南京市 | X23: PME2006 | Y23: 孙娟 | Z23: 45803 | AA23: =DATEDIF(Z23,TODAY(),"M") -> 15 | AB23: =LOOKUP(AA23,{0,1,3},{"1个月以内","3个月以内","3个月以上"}) -> 3个月以上 | AF23: 张鑫 | AG23: 冯雅琪 | AH23: 青岛大学附属医院 | AI23: 曲美洁 | AJ23: 黑标
H24: 张鑫 | I24: 鲁景霄 | J24: HO00001431 | K24: 淄博市中心医院 | L24: 高怀清 | M24: 脑血管 | N24: 神经内科 | O24: B | R24: DME2001 | S24: 郑家成 | T24: HO00208681 | U24: 东南大学附属中大医院江北院区 | V24: 江苏 | W24: 南京市 | X24: PME2006 | Y24: 孙娟 | Z24: 45803 | AA24: =DATEDIF(Z24,TODAY(),"M") -> 15 | AB24: =LOOKUP(AA24,{0,1,3},{"1个月以内","3个月以内","3个月以上"}) -> 3个月以上 | AF24: 张鑫 | AG24: 冯雅琪 | AH24: 青岛大学附属医院 | AI24: 王亚男 | AJ24: 黑标
H25: 张鑫 | I25: 鲁景霄 | J25: HO00001431 | K25: 淄博市中心医院 | L25: 甘红梅 | M25: 脑血管 | N25: 神经内科 | O25: B | R25: DME2001 | S25: 郑家成 | T25: HO00000952 | U25: 仪征市人民医院 | V25: 江苏 | W25: 扬州市 | X25: PME2012 | Y25: 高佳怡 | Z25: 45839 | AA25: =DATEDIF(Z25,TODAY(),"M") -> 13 | AB25: =LOOKUP(AA25,{0,1,3},{"1个月以内","3个月以内","3个月以上"}) -> 3个月以上 | AF25: 张鑫 | AG25: 冯雅琪 | AH25: 青岛大学附属医院 | AI25: 宋敬卉 | AJ25: 黑标
H26: 张鑫 | I26: 李明晖 | J26: HO00001482 | K26: 青岛市市立医院 | L26: 王新 | M26: 头痛 | N26: 神经内科 | O26: A | R26: DME2001 | S26: 郑家成 | T26: HO00000953 | U26: 泰兴市人民医院 | V26: 江苏 | W26: 泰州市 | X26: PME2012 | Y26: 高佳怡 | Z26: 45839 | AA26: =DATEDIF(Z26,TODAY(),"M") -> 13 | AB26: =LOOKUP(AA26,{0,1,3},{"1个月以内","3个月以内","3个月以上"}) -> 3个月以上 | AF26: 张鑫 | AG26: 冯雅琪 | AH26: 青岛心血管病医院 | AI26: 毛丽娜 | AJ26: 红标
H27: 张鑫 | I27: 李明晖 | J27: HO00001482 | K27: 青岛市市立医院 | L27: 孙铭宏 | M27: 眩晕 | N27: 耳鼻喉科 | O27: C | R27: DME2001 | S27: 郑家成 | T27: HO00000954 | U27: 泰州市第二人民医院 | V27: 江苏 | W27: 泰州市 | X27: PME2012 | Y27: 高佳怡 | Z27: 45839 | AA27: =DATEDIF(Z27,TODAY(),"M") -> 13 | AB27: =LOOKUP(AA27,{0,1,3},{"1个月以内","3个月以内","3个月以上"}) -> 3个月以上 | AF27: 张鑫 | AG27: 冯雅琪 | AH27: 青岛心血管病医院 | AI27: 薛慧芳 | AJ27: 绿标
H28: 张鑫 | I28: 李明晖 | J28: HO00001482 | K28: 青岛市市立医院 | L28: 李永团 | M28: 眩晕 | N28: 耳鼻喉科 | O28: C | R28: DME2001 | S28: 郑家成 | T28: HO00000968 | U28: 江苏省苏北人民医院 | V28: 江苏 | W28: 扬州市 | X28: PME2012 | Y28: 高佳怡 | Z28: 45839 | AA28: =DATEDIF(Z28,TODAY(),"M") -> 13 | AB28: =LOOKUP(AA28,{0,1,3},{"1个月以内","3个月以内","3个月以上"}) -> 3个月以上 | AF28: 张鑫 | AG28: 冯雅琪 | AH28: 青岛心血管病医院 | AI28: 董丽丽 | AJ28: 黑标
H29: 张鑫 | I29: 邹誉颍 | J29: HO00001522 | K29: 烟台毓璜顶医院 | L29: 高晓玉 | M29: 头痛 | N29: 神经内科 | O29: A | R29: DME2001 | S29: 郑家成 | T29: HO00000969 | U29: 扬州大学附属医院(原扬州市第一人民医院) | V29: 江苏 | W29: 扬州市 | X29: PME2012 | Y29: 高佳怡 | Z29: 45839 | AA29: =DATEDIF(Z29,TODAY(),"M") -> 13 | AB29: =LOOKUP(AA29,{0,1,3},{"1个月以内","3个月以内","3个月以上"}) -> 3个月以上 | AF29: 张鑫 | AG29: 陈彩虹 | AH29: 青岛大学附属医院西海岸院区 | AI29: 李宏 | AJ29: 红标
H30: 张鑫 | I30: 冯雅琪 | J30: HO00001483 | K30: 青岛市中医医院 | L30: 于永鹏 | M30: 头痛 | N30: 神经内科 | O30: A | R30: DME2001 | S30: 郑家成 | T30: HO00000970 | U30: 扬州市中医院 | V30: 江苏 | W30: 扬州市 | X30: PME2012 | Y30: 高佳怡 | Z30: 45839 | AA30: =DATEDIF(Z30,TODAY(),"M") -> 13 | AB30: =LOOKUP(AA30,{0,1,3},{"1个月以内","3个月以内","3个月以上"}) -> 3个月以上 | AF30: 张鑫 | AG30: 陈彩虹 | AH30: 西海岸中心医院 | AI30: 王传林 | AJ30: 绿标
H31: 张鑫 | I31: 冯雅琪 | J31: HO00370760 | K31: 青岛大学附属医院崂山院区 | L31: 王琨 | M31: 头痛 | N31: 神经内科 | O31: A | R31: DME2001 | S31: 郑家成 | T31: HO00000983 | U31: 扬州友好医院 | V31: 江苏 | W31: 扬州市 | X31: PME2012 | Y31: 高佳怡 | Z31: 45839 | AA31: =DATEDIF(Z31,TODAY(),"M") -> 13 | AB31: =LOOKUP(AA31,{0,1,3},{"1个月以内","3个月以内","3个月以上"}) -> 3个月以上 | AF31: 张鑫 | AG31: 陈彩虹 | AH31: 康复大学青岛中心医院 | AI31: 相波 | AJ31: 红标
H32: 张鑫 | I32: 冯雅琪 | J32: HO00001483 | K32: 青岛市中医医院 | L32: 陈晓宇 | M32: 眩晕 | N32: 耳鼻喉科 | O32: C | R32: DME2001 | S32: 郑家成 | T32: HO00001005 | U32: 江苏省第一荣军优抚医院 | V32: 江苏 | W32: 扬州市 | X32: PME2012 | Y32: 高佳怡 | Z32: 45839 | AA32: =DATEDIF(Z32,TODAY(),"M") -> 13 | AB32: =LOOKUP(AA32,{0,1,3},{"1个月以内","3个月以内","3个月以上"}) -> 3个月以上 | AF32: 张鑫 | AG32: 陈彩虹 | AH32: 康复大学青岛中心医院 | AI32: 李海燕 | AJ32: 红标
H33: 张鑫 | I33: 冯雅琪 | J33: HO00001483 | K33: 青岛市中医医院 | L33: 马晓维 | M33: 眩晕 | N33: 神经内科 | O33: C | R33: DME2001 | S33: 郑家成 | T33: HO00001006 | U33: 泰州市人民医院 | V33: 江苏 | W33: 泰州市 | X33: PME2012 | Y33: 高佳怡 | Z33: 45839 | AA33: =DATEDIF(Z33,TODAY(),"M") -> 13 | AB33: =LOOKUP(AA33,{0,1,3},{"1个月以内","3个月以内","3个月以上"}) -> 3个月以上 | AF33: 张鑫 | AG33: 陈彩虹 | AH33: 西海岸中心医院 | AI33: 高山 | AJ33: 绿标
... H432: 张鑫 | I432: 冯雅琪 | J432: HO00001477 | K432: 青岛大学附属医院 | L432: 王乃东 | M432: 脑血管 | N432: 神经内科 | O432: B | R432: DME2005 | S432: 张鑫 | T432: HO00025649 | U432: 淄博市张店区中医院 | V432: 山东 | W432: 淄博市 | X432: PME2043 | Y432: 鲁景霄 | Z432: 45985 | AA432: =DATEDIF(Z432,TODAY(),"M") -> 9 | AB432: =LOOKUP(AA432,{0,1,3},{"1个月以内","3个月以内","3个月以上"}) -> 3个月以上 | AF432: 郑家成 | AG432: 刘银 | AH432: 南京脑科医院 | AI432: 沙瑞娟 | AJ432: 绿标
H433: 张鑫 | I433: 邹誉颍 | J433: #N/A | K433: 招远人民医院 | L433: 刘卫业 | M433: 疼痛 | N433: 疼痛科 | O433: D | R433: DME2005 | S433: 张鑫 | T433: HO00041959 | U433: 淄博昌国医院有限公司 | V433: 山东 | W433: 淄博市 | X433: PME2043 | Y433: 鲁景霄 | Z433: 45985 | AA433: =DATEDIF(Z433,TODAY(),"M") -> 9 | AB433: =LOOKUP(AA433,{0,1,3},{"1个月以内","3个月以内","3个月以上"}) -> 3个月以上 | AF433: 郑家成 | AG433: 刘银 | AH433: 南京脑科医院 | AI433: 陈道文 | AJ433: 绿标
H434: 卜先峰 | I434: 许恺丽 | J434: HO00002956 | K434: 安徽医科大学第一附属医院南区 | L434: 卫玲 | M434: 脑血管 | N434: 神经内科 | O434: B | R434: DME2005 | S434: 张鑫 | T434: HO00286401 | U434: 淄博市中心医院(西院区) | V434: 山东 | W434: 淄博市 | X434: PME2043 | Y434: 鲁景霄 | Z434: 45985 | AA434: =DATEDIF(Z434,TODAY(),"M") -> 9 | AB434: =LOOKUP(AA434,{0,1,3},{"1个月以内","3个月以内","3个月以上"}) -> 3个月以上 | AF434: 郑家成 | AG434: 刘银 | AH434: 南京脑科医院 | AI434: 陆杰 | AJ434: 绿标
H435: 郑家成 | I435: 缪苏琴 | J435: HO00000941 | K435: 常州市第二人民医院 | L435: 王全海 | M435: 其他 | N435: 其他 | O435: D | R435: DME2006 | S435: 卜先峰 | T435: HO00000004 | U435: 马鞍山市人民医院 | V435: 安徽 | W435: 马鞍山市 | X435: PME2003 | Y435: 孙小寒 | Z435: 46204 | AA435: =DATEDIF(Z435,TODAY(),"M") -> 1 | AB435: =LOOKUP(AA435,{0,1,3},{"1个月以内","3个月以内","3个月以上"}) -> 3个月以内 | AF435: 郑家成 | AG435: 刘银 | AH435: 南京脑科医院 | AI435: 黄琳 | AJ435: 绿标
H436: 郑家成 | I436: 杨帆 | J436: HO00000972 | K436: 中国人民解放军东部战区总医院 | L436: 肖露露 | M436: 脑血管 | N436: 神经内科 | O436: B | R436: DME2006 | S436: 卜先峰 | T436: HO00000013 | U436: 芜湖市第一人民医院 | V436: 安徽 | W436: 芜湖市 | X436: PME2003 | Y436: 孙小寒 | Z436: 46204 | AA436: =DATEDIF(Z436,TODAY(),"M") -> 1 | AB436: =LOOKUP(AA436,{0,1,3},{"1个月以内","3个月以内","3个月以上"}) -> 3个月以内 | AF436: 郑家成 | AG436: 刘银 | AH436: 南京脑科医院 | AI436: 陈洁 | AJ436: 绿标
H437: 孟鈃 | I437: 王方方 | J437: HO00000958 | K437: 江苏省人民医院 | L437: 杨文平 | M437: 脑血管 | N437: 神经内科 | O437: B | R437: DME2006 | S437: 卜先峰 | T437: HO00000014 | U437: 华东师范大学附属芜湖医院 | V437: 安徽 | W437: 芜湖市 | X437: PME2003 | Y437: 孙小寒 | Z437: 46204 | AA437: =DATEDIF(Z437,TODAY(),"M") -> 1 | AB437: =LOOKUP(AA437,{0,1,3},{"1个月以内","3个月以内","3个月以上"}) -> 3个月以内 | AF437: 郑家成 | AG437: 刘银 | AH437: 南京脑科医院 | AI437: 许利刚 | AJ437: 绿标
H438: 孟鈃 | I438: 章智程 | J438: HO00001134 | K438: 徐州矿务集团总医院暨徐州医科大学院第二附属医院 | L438: 杨华 | M438: 脑血管 | N438: 神经内科 | O438: B | R438: DME2006 | S438: 卜先峰 | T438: HO00000018 | U438: 皖南医学院第二附属医院 | V438: 安徽 | W438: 芜湖市 | X438: PME2003 | Y438: 孙小寒 | Z438: 46204 | AA438: =DATEDIF(Z438,TODAY(),"M") -> 1 | AB438: =LOOKUP(AA438,{0,1,3},{"1个月以内","3个月以内","3个月以上"}) -> 3个月以内 | AF438: 郑家成 | AG438: 刘银 | AH438: 南京脑科医院 | AI438: 田敏捷 | AJ438: 绿标
...

Sheet 3M+作战地图排名
A1: 计算规则：60%客户破冰数+40%3M提及数 | M1: 作战地图排名 | U1: 纬度1：计算规则：破冰客户数月≥10个的员工数40%，3m客户数月≥6个的员工数40%，C类破冰客户数月≥4个员工数20% | Z1: 6月 | AB1: 3M排名 | AJ1: 纬度1：计算规则：50%考核3M的员工数占比+50%每周都有三天及以上产3M的员工数占比 | AP1: 6月 | AT1: 作战地图排名 | BB1: 纬度1：计算规则：破冰客户数周≥10个的员工数40%，3m客户数周≥6个的员工数40%，C类破冰客户数周≥4个员工数20% | BG1: 7月第1周 | BI1: 3M排名 | BQ1: 纬度1：计算规则：50%考核3M的员工数占比+50%三天以上产3M员工数占比 | BW1: 7月第1周 | CA1: 作战地图排名 | CI1: 纬度1：计算规则：破冰客户数周≥10个的员工数40%，3m客户数周≥6个的员工数40%，C类破冰客户数周≥4个员工数20% | CN1: 7月第2周 | CP1: 3M排名 | CX1: 纬度1：计算规则：50%考核3M的员工数占比+50%三天以上产3M员工数占比 | DD1: 7月第2周 | DH1: 作战地图排名 | DP1: 纬度1：计算规则：破冰客户数周≥10个的员工数40%，3m客户数周≥6个的员工数40%，C类破冰客户数周≥4个员工数20% | DU1: 7月第3周 | DW1: 3M排名 | EE1: 纬度1：计算规则：50%考核3M的员工数占比+50%三天以上产3M员工数占比 | EK1: 7月第3周 | EO1: 作战地图排名 | EW1: 纬度1：计算规则：破冰客户数周≥10个的员工数40%，3m客户数周≥6个的员工数40%，C类破冰客户数周≥4个员工数20% | FB1: 7月第4周 | FD1: 3M排名 | FL1: 纬度1：计算规则：50%考核3M的员工数占比+50%三天以上产3M员工数占比 | FR1: 7月第4周 | FV1: 作战地图排名 | GD1: 纬度1：计算规则：破冰客户数周≥10个的员工数40%，3m客户数周≥6个的员工数40%，C类破冰客户数周≥4个员工数20% | GI1: 7月 | GK1: 3M排名 | GS1: 纬度1：计算规则：50%考核3M的员工数占比+50%三天以上产3M员工数占比 | GY1: 7月 | HC1: 作战地图排名 | HK1: 纬度1：计算规则：破冰客户数周≥10个的员工数40%，3m客户数周≥6个的员工数40%，C类破冰客户数周≥4个员工数20% | HP1: 8月第1周 | HR1: 3M排名 | HZ1: 纬度1：计算规则：50%考核3M的员工数占比+50%三天以上产3M员工数占比 | IF1: 8月第1周 | IJ1: 作战地图排名 | IT1: 3M排名 | JB1: 作战地图排名 | JL1: 纬度1：计算规则：破冰客户数周≥10个的员工数40%，3m客户数周≥6个的员工数40%，C类破冰客户数周≥4个员工数20% | JQ1: 8月第2周 | JS1: 3M排名 | KA1: 纬度1：计算规则：50%考核3M的员工数占比+50%三天以上产3M员工数占比 | KG1: 8月第2周 | KL1: 作战地图排名 | KV1: 3M排名 | LD1: 作战地图排名 | LN1: 3M排名 | LV1: 作战地图排名 | MF1: 3M排名 | MN1: 作战地图排名 | MX1: 3M排名 | NF1: 作战地图排名 | NP1: 纬度1：计算规则：破冰客户数周≥10个的员工数40%，3m客户数周≥6个的员工数40%，C类破冰客户数周≥4个员工数20% | NU1: 8月第3周 | NW1: 3M排名 | OE1: 纬度1：计算规则：50%考核3M的员工数占比+50%三天以上产3M员工数占比 | OK1: 8月第3周 | OO1: 作战地图排名 | OY1: 3M排名 | PG1: 作战地图排名 | PQ1: 3M排名 | PY1: 作战地图排名 | QI1: 3M排名 | QQ1: 作战地图排名 | RA1: 3M排名 | RJ1: 作战地图排名 | RT1: 纬度1：计算规则：破冰客户数周≥10个的员工数40%，3m客户数周≥6个的员工数40%，C类破冰客户数周≥4个员工数20% | RY1: 8月第4周 | SA1: 3M排名 | SI1: 纬度1：计算规则：50%考核3M的员工数占比+50%三天以上产3M员工数占比 | SO1: 8月第4周
A2: Q1 | D2: 7.2 | E2: 100 | F2: 464 | G2: 100 | M2: 计算规则：50%处方客户数+50%3M客户数 | R2: 6月 | U2: DM | V2: 破冰客户数≥10的员工数 | W2: 3M客户数≥6的员工数 | X2: C类破冰客户数≥4的员工数 | Y2: 计算 | Z2: 排名 | AB2: 计算规则：40%3M客户数+60%3M提及数 | AG2: 6月 | AJ2: DM | AK2: HC数 | AL2: 在岗人数 | AM2: 产生3M员工数 | AN2: 占比 | AO2: 每周3天及以上产3M员工 | AP2: 占比 | AQ2: 计算 | AR2: 排名 | AT2: 计算规则：50%处方客户数+50%3M客户数 | AY2: 7月第1周 | BB2: DM | BC2: 客户数≥10的员工数 | BD2: 3M客户数≥6的员工数 | BE2: C类客户数≥4的员工数 | BF2: 计算 | BG2: 排名 | BI2: 计算规则：40%3M客户数+60%3M提及数 | BN2: 7月第1周 | BQ2: DM | BR2: HC数 | BS2: 在岗人数 | BT2: 产生3M员工数 | BU2: 占比 | BV2: 三天及以上产3M员工 | BW2: 占比 | BX2: 计算 | BY2: 排名 | CA2: 计算规则：50%处方客户数+50%3M客户数 | CF2: 7月第2周 | CI2: DM | CJ2: 客户数≥10的员工数 | CK2: 3M客户数≥6的员工数 | CL2: C类客户数≥4的员工数 | CM2: 计算 | CN2: 排名 | CP2: 计算规则：40%3M客户数+60%3M提及数 | CU2: 7月第2周 | CX2: DM | CY2: HC数 | CZ2: 在岗人数 | DA2: 产生3M员工数 | DB2: 占比 | DC2: 三天及以上产3M员工 | DD2: 占比 | DE2: 计算 | DF2: 排名 | DH2: 计算规则：50%处方客户数+50%3M客户数 | DM2: 7月第3周 | DP2: DM | DQ2: 客户数≥10的员工数 | DR2: 3M客户数≥6的员工数 | DS2: C类客户数≥4的员工数 | DT2: 计算 | DU2: 排名 | DW2: 计算规则：40%3M客户数+60%3M提及数 | EB2: 7月第3周 | EE2: DM | EF2: HC数 | EG2: 在岗人数 | EH2: 产生3M员工数 | EI2: 占比 | EJ2: 三天及以上产3M员工 | EK2: 占比 | EL2: 计算 | EM2: 排名 | EO2: 计算规则：50%处方客户数+50%3M客户数 | ET2: 7月第4周 | EW2: DM | EX2: 客户数≥10的员工数 | EY2: 3M客户数≥6的员工数 | EZ2: C类客户数≥4的员工数 | FA2: 计算 | FB2: 排名 | FD2: 计算规则：40%3M客户数+60%3M提及数 | FI2: 7月第4周 | FL2: DM | FM2: HC数 | FN2: 在岗人数 | FO2: 产生3M员工数 | FP2: 占比 | FQ2: 三天及以上产3M员工 | FR2: 占比 | FS2: 计算 | FT2: 排名 | FV2: 计算规则：50%处方客户数+50%3M客户数 | GA2: 7月 | GD2: DM | GE2: 客户数≥10的员工数 | GF2: 3M客户数≥6的员工数 | GG2: C类客户数≥4的员工数 | GH2: 计算 | GI2: 排名 | GK2: 计算规则：40%3M客户数+60%3M提及数 | GP2: 7月 | GS2: DM | GT2: HC数 | GU2: 在岗人数 | GV2: 产生3M员工数 | GW2: 占比 | GX2: 三天及以上产3M员工 | GY2: 占比 | GZ2: 计算 | HA2: 排名 | HC2: 计算规则：50%处方客户数+50%3M客户数 | HH2: 8月第1周 | HK2: DM | HL2: 客户数≥10的员工数 | HM2: 3M客户数≥6的员工数 | HN2: C类客户数≥4的员工数 | HO2: 计算 | HP2: 排名 | HR2: 计算规则：40%3M客户数+60%3M提及数 | HW2: 8月第1周 | HZ2: DM | IA2: HC数 | IB2: 在岗人数 | IC2: 产生3M员工数 | ID2: 占比 | IE2: 三天及以上产3M员工 | IF2: 占比 | IG2: 计算 | IH2: 排名 | IJ2: 计算规则：40%处方客户数+30%C类客户数+30%3M客户数 | IQ2: 46247 | IT2: 计算规则：50%3M客户数+50%3M提及数 | IY2: 46247 | JB2: 计算规则：40%处方客户数+30%C类客户数+30%3M客户数 | JI2: 8月第2周 | JL2: DM | JM2: 客户数≥10的员工数 | JN2: 3M客户数≥6的员工数 | JO2: C类客户数≥4的员工数 | JP2: 计算 | JQ2: 排名 | JS2: 计算规则：50%3M客户数+50%3M提及数 | JX2: 8月第2周 | KA2: DM | KB2: HC数 | KC2: 在岗人数 | KD2: 产生3M员工数 | KE2: 占比 | KF2: 三天及以上产3M员工 | KG2: 占比 | KH2: 计算 | KI2: 排名 | KL2: 计算规则：40%处方客户数+30%C类客户数+30%3M客户数 | KS2: 46251 | KV2: 计算规则：50%3M客户数+50%3M提及数 | LA2: 46251 | LD2: 计算规则：40%处方客户数+30%C类客户数+30%3M客户数 | LK2: 46252 | LN2: 计算规则：50%3M客户数+50%3M提及数 | LS2: 46252 | LV2: 计算规则：40%处方客户数+30%C类客户数+30%3M客户数 | MC2: 46253 | MF2: 计算规则：50%3M客户数+50%3M提及数 | MK2: 46253 | MN2: 计算规则：40%处方客户数+30%C类客户数+30%3M客户数 | MU2: 46254 | MX2: 计算规则：50%3M客户数+50%3M提及数 | NC2: 46254 | NF2: 计算规则：40%处方客户数+30%C类客户数+30%3M客户数 | NM2: 8月第3周 | NP2: DM | NQ2: 客户数≥10的员工数 | NR2: 3M客户数≥6的员工数 | NS2: C类客户数≥4的员工数 | NT2: 计算 | NU2: 排名 | NW2: 计算规则：50%3M客户数+50%3M提及数 | OB2: 8月第3周 | OE2: DM | OF2: HC数 | OG2: 在岗人数 | OH2: 产生3M员工数 | OI2: 占比 | OJ2: 三天及以上产3M员工 | OK2: 占比 | OL2: 计算 | OM2: 排名 | OO2: 计算规则：40%处方客户数+30%C类客户数+30%3M客户数 | OV2: 46258 | OY2: 计算规则：50%3M客户数+50%3M提及数 | PD2: 46258 | PG2: 计算规则：40%处方客户数+30%C类客户数+30%3M客户数 | PN2: 46259 | PQ2: 计算规则：50%3M客户数+50%3M提及数 | PV2: 46259 | PY2: 计算规则：40%处方客户数+30%C类客户数+30%3M客户数 | QF2: 46260 | QI2: 计算规则：50%3M客户数+50%3M提及数 | QN2: 46260 | QQ2: 计算规则：40%处方客户数+30%C类客户数+30%3M客户数 | QX2: 46261 | RA2: 计算规则：50%3M客户数+50%3M提及数 | RF2: 46261 | RJ2: 计算规则：40%处方客户数+30%C类客户数+30%3M客户数 | RQ2: 8月第4周 | RT2: DM | RU2: 客户数≥10的员工数 | RV2: 3M客户数≥6的员工数 | RW2: C类客户数≥4的员工数 | RX2: 计算 | RY2: 排名 | SA2: 计算规则：50%3M客户数+50%3M提及数 | SF2: 8月第4周 | SI2: DM | SJ2: HC数 | SK2: 在岗人数 | SL2: 产生3M员工数 | SM2: 占比 | SN2: 三天及以上产3M员工 | SO2: 占比 | SP2: 计算 | SQ2: 排名
A3: DM | B3: 入职划分 | C3: 破冰客户数 | D3: 破冰率 | E3: 辅助列 | F3: 3M提及数 | G3: 辅助列 | H3: 计算 | M3: DM | N3: MICS | O3: 入职划分 | P3: 处方客户数 | Q3: 3M客户数 | R3: 计算 | S3: 排名 | U3: 张鑫 | V3: 6 | W3: 5 | X3: 3 | Y3: =V3*40%+W3*40%+X3*20% -> 5 | Z3: =RANK(Y3,$Y$3:$Y$8) -> 1 | AB3: DM | AC3: MICS | AD3: 入职划分 | AE3: 3M客户数 | AF3: 3M提及数 | AG3: 计算 | AH3: 排名 | AJ3: 李路 | AK3: 9 | AL3: 6 | AM3: 6 | AN3: =AM3/AL3 -> 1 | AO3: 6 | AP3: =AO3/AL3 -> 1 | AQ3: =50%*AN3+50%*AP3 -> 1 | AR3: =RANK(AQ3,$AQ$3:$AQ$8) -> 1 | AT3: DM | AU3: MICS | AV3: 入职划分 | AW3: 处方客户数 | AX3: 3M客户数 | AY3: 计算 | AZ3: 排名 | BB3: 张鑫 | BC3: 0 | BD3: 0 | BE3: 2 | BF3: =BC3*40%+BD3*40%+BE3*20% -> 0.4 | BG3: =RANK(BF3,$BF$3:$BF$8) -> 1 | BI3: DM | BJ3: MICS | BK3: 入职划分 | BL3: 3M客户数 | BM3: 3M提及数 | BN3: 计算 | BO3: 排名 | BQ3: 何方禹 | BR3: 8 | BS3: 8 | BT3: 7 | BU3: =BT3/BS3 -> 0.875 | BV3: 6 | BW3: =BV3/BS3 -> 0.75 | BX3: =50%*BU3+50%*BW3 -> 0.8125 | BY3: =RANK(BX3,$BX$3:$BX$8) -> 1 | CA3: DM | CB3: MICS | CC3: 入职划分 | CD3: 处方客户数 | CE3: 3M客户数 | CF3: 计算 | CG3: 排名 | CI3: 张鑫 | CJ3: 1 | CK3: 0 | CL3: 3 | CM3: =CJ3*40%+CK3*40%+CL3*20% -> 1 | CN3: =RANK(CM3,$CM$3:$CM$8) -> 1 | CP3: DM | CQ3: MICS | CR3: 入职划分 | CS3: 3M客户数 | CT3: 3M提及数 | CU3: 计算 | CV3: 排名 | CX3: 张鑫 | CY3: 7 | CZ3: 6 | DA3: 7 | DB3: =DA3/CZ3 -> 1.1666667 | DC3: 6 | DD3: =DC3/CZ3 -> 1 | DE3: =50%*DB3+50%*DD3 -> 1.0833333 | DF3: =RANK(DE3,$DE$3:$DE$8) -> 1 | DH3: DM | DI3: MICS | DJ3: 入职划分 | DK3: 处方客户数 | DL3: 3M客户数 | DM3: 计算 | DN3: 排名 | DP3: 张鑫 | DQ3: 1 | DR3: 2 | DS3: 2 | DT3: =DQ3*40%+DR3*40%+DS3*20% -> 1.6 | DU3: =RANK(DT3,$DT$3:$DT$8) -> 1 | DW3: DM | DX3: MICS | DY3: 入职划分 | DZ3: 3M客户数 | EA3: 3M提及数 | EB3: 计算 | EC3: 排名 | EE3: 张鑫 | EF3: 7 | EG3: 6 | EH3: 6 | EI3: =EH3/EG3 -> 1 | EJ3: 5 | EK3: =EJ3/EG3 -> 0.83333333 | EL3: =50%*EI3+50%*EK3 -> 0.91666667 | EM3: =RANK(EL3,$EL$3:$EL$8) -> 1 | EO3: DM | EP3: MICS | EQ3: 入职划分 | ER3: 处方客户数 | ES3: 3M客户数 | ET3: 计算 | EU3: 排名 | EW3: 张鑫 | EX3: 1 | EY3: 1 | EZ3: 3 | FA3: =EX3*40%+EY3*40%+EZ3*20% -> 1.4 | FB3: =RANK(FA3,$FA$3:$FA$8) -> 1 | FD3: DM | FE3: MICS | FF3: 入职划分 | FG3: 3M客户数 | FH3: 3M提及数 | FI3: 计算 | FJ3: 排名 | FL3: 李路 | FM3: 9 | FN3: 6 | FO3: 5 | FP3: =FO3/FN3 -> 0.83333333 | FQ3: 5 | FR3: =FQ3/FN3 -> 0.83333333 | FS3: =50%*FP3+50%*FR3 -> 0.83333333 | FT3: =RANK(FS3,$FS$3:$FS$8) -> 1 | FV3: DM | FW3: MICS | FX3: 入职划分 | FY3: 处方客户数 | FZ3: 3M客户数 | GA3: 计算 | GB3: 排名 | GD3: 张鑫 | GE3: 6 | GF3: 5 | GG3: 4 | GH3: =GE3*40%+GF3*40%+GG3*20% -> 5.2 | GI3: =RANK(GH3,$GH$3:$GH$8) -> 1 | GK3: DM | GL3: MICS | GM3: 入职划分 | GN3: 3M客户数 | GO3: 3M提及数 | GP3: 计算 | GQ3: 排名 | GS3: 李路 | GT3: 9 | GU3: 6 | GV3: 6 | GW3: =GV3/GU3 -> 1 | GX3: 4 | GY3: =GX3/GU3 -> 0.66666667 | GZ3: =50%*GW3+50%*GY3 -> 0.83333333 | HA3: =RANK(GZ3,$GZ$3:$GZ$8) -> 1 | HC3: DM | HD3: MICS | HE3: 入职划分 | HF3: 处方客户数 | HG3: 3M客户数 | HH3: 计算 | HI3: 排名 | HK3: 张鑫 | HL3: 2 | HM3: 3 | HN3: 3 | HO3: =HL3*40%+HM3*40%+HN3*20% -> 2.6 | HP3: =RANK(HO3,$HO$3:$HO$8) -> 1 | HR3: DM | HS3: MICS | HT3: 入职划分 | HU3: 3M客户数 | HV3: 3M提及数 | HW3: 计算 | HX3: 排名 | HZ3: 张鑫 | IA3: 7 | IB3: 5 | IC3: 5 | ID3: =IC3/IB3 -> 1 | IE3: 4 | IF3: =IE3/IB3 -> 0.8 | IG3: =50%*ID3+50%*IF3 -> 0.9 | IH3: =RANK(IG3,$IG$3:$IG$8) -> 1 | IJ3: DM | IK3: MICS | IL3: 入职划分 | IM3: 处方客户数 | IN3: C类客户数 | IO3: 3M客户数 | IP3: C类客户占比 | IQ3: 计算 | IR3: 排名 | IT3: DM | IU3: MICS | IV3: 入职划分 | IW3: 3M客户数 | IX3: 3M提及数 | IY3: 计算 | IZ3: 排名 | JB3: DM | JC3: MICS | JD3: 入职划分 | JE3: 处方客户数 | JF3: 3M客户数 | JG3: C类客户数 | JH3: C类客户占比 | JI3: 计算 | JJ3: 排名 | JL3: 张鑫 | JM3: 2 | JN3: 2 | JO3: 2 | JP3: =JM3*40%+JN3*40%+JO3*20% -> 2 | JQ3: =RANK(JP3,$JP$3:$JP$8) -> 1 | JS3: DM | JT3: MICS | JU3: 入职划分 | JV3: 3M客户数 | JW3: 3M提及数 | JX3: 计算 | JY3: 排名 | KA3: 李路 | KB3: 9 | KC3: 5 | KD3: 5 | KE3: =KD3/KC3 -> 1 | KF3: 5 | KG3: =KF3/KC3 -> 1 | KH3: =50%*KE3+50%*KG3 -> 1 | KI3: =RANK(KH3,$KH$3:$KH$8) -> 1 | KL3: DM | KM3: MICS | KN3: 入职划分 | KO3: 处方客户数 | KP3: 3M客户数 | KQ3: C类客户数 | KR3: C类客户占比 | KS3: 计算 | KT3: 排名 | KV3: DM | KW3: MICS | KX3: 入职划分 | KY3: 3M客户数 | KZ3: 3M提及数 | LA3: 计算 | LB3: 排名 | LD3: DM | LE3: MICS | LF3: 入职划分 | LG3: 处方客户数 | LH3: 3M客户数 | LI3: C类客户数 | LJ3: C类客户占比 | LK3: 计算 | LL3: 排名 | LN3: DM | LO3: MICS | LP3: 入职划分 | LQ3: 3M客户数 | LR3: 3M提及数 | LS3: 计算 | LT3: 排名 | LV3: DM | LW3: MICS | LX3: 入职划分 | LY3: 处方客户数 | LZ3: 3M客户数 | MA3: C类客户数 | MB3: C类客户占比 | MC3: 计算 | MD3: 排名 | MF3: DM | MG3: MICS | MH3: 入职划分 | MI3: 3M客户数 | MJ3: 3M提及数 | MK3: 计算 | ML3: 排名 | MN3: DM | MO3: MICS | MP3: 入职划分 | MQ3: 处方客户数 | MR3: 3M客户数 | MS3: C类客户数 | MT3: C类客户占比 | MU3: 计算 | MV3: 排名 | MX3: DM | MY3: MICS | MZ3: 入职划分 | NA3: 3M客户数 | NB3: 3M提及数 | NC3: 计算 | ND3: 排名 | NF3: DM | NG3: MICS | NH3: 入职划分 | NI3: 处方客户数 | NJ3: 3M客户数 | NK3: C类客户数 | NL3: C类客户占比 | NM3: 计算 | NN3: 排名 | NP3: 张鑫 | NQ3: 0 | NR3: 2 | NS3: 1 | NT3: =NQ3*40%+NR3*40%+NS3*20% -> 1 | NU3: =RANK(NT3,$NT$3:$NT$8) -> 1 | NW3: DM | NX3: MICS | NY3: 入职划分 | NZ3: 3M客户数 | OA3: 3M提及数 | OB3: 计算 | OC3: 排名 | OE3: 李路 | OF3: 9 | OG3: 5 | OH3: 5 | OI3: =OH3/OG3 -> 1 | OJ3: 5 | OK3: =OJ3/OG3 -> 1 | OL3: =50%*OI3+50%*OK3 -> 1 | OM3: =RANK(OL3,$OL$3:$OL$8) -> 1 | OO3: DM | OP3: MICS | OQ3: 入职划分 | OR3: 处方客户数 | OS3: 3M客户数 | OT3: C类客户数 | OU3: C类客户占比 | OV3: 计算 | OW3: 排名 | OY3: DM | OZ3: MICS | PA3: 入职划分 | PB3: 3M客户数 | PC3: 3M提及数 | PD3: 计算 | PE3: 排名 | PG3: DM | PH3: MICS | PI3: 入职划分 | PJ3: 处方客户数 | PK3: 3M客户数 | PL3: C类客户数 | PM3: C类客户占比 | PN3: 计算 | PO3: 排名 | PQ3: DM | PR3: MICS | PS3: 入职划分 | PT3: 3M客户数 | PU3: 3M提及数 | PV3: 计算 | PW3: 排名 | PY3: DM | PZ3: MICS | QA3: 入职划分 | QB3: 处方客户数 | QC3: 3M客户数 | QD3: C类客户数 | QE3: C类客户占比 | QF3: 计算 | QG3: 排名 | QI3: DM | QJ3: MICS | QK3: 入职划分 | QL3: 3M客户数 | QM3: 3M提及数 | QN3: 计算 | QO3: 排名 | QQ3: DM | QR3: MICS | QS3: 入职划分 | QT3: 处方客户数 | QU3: 3M客户数 | QV3: C类客户数 | QW3: C类客户占比 | QX3: 计算 | QY3: 排名 | RA3: DM | RB3: MICS | RC3: 入职划分 | RD3: 3M客户数 | RE3: 3M提及数 | RF3: 计算 | RG3: 排名 | RJ3: DM | RK3: MICS | RL3: 入职划分 | RM3: 处方客户数 | RN3: 3M客户数 | RO3: C类客户数 | RP3: C类客户占比 | RQ3: 计算 | RR3: 排名 | RT3: 李路 | RU3: 2 | RV3: 0 | RW3: 1 | RX3: 1 | RY3: 1 | SA3: DM | SB3: MICS | SC3: 入职划分 | SD3: 3M客户数 | SE3: 3M提及数 | SF3: 计算 | SG3: 排名 | SI3: 张鑫 | SJ3: 7 | SK3: 5 | SL3: 5 | SM3: 1 | SN3: 5 | SO3: 1 | SP3: 1 | SQ3: 1
